Workbook

Sheet 00_Instrucciones
A1: DISC para Gestión de Equipos — Archivo maestro para reporte gráfico
A2: Propósito | B2: Consolidar ítems, clave, reglas de puntuación, rúbrica de retroalimentación y datos base para que un desarrollador gráfico genere reportes individuales y de equipo.
A3: Formato de aplicación | B3: Elección forzada: en cada ítem se marca una opción como MÁS me describe y una opción distinta como MENOS me describe.
A4: Regla de puntaje | B4: MÁS = +1 para el estilo de la opción seleccionada. MENOS = -1 para el estilo de la opción seleccionada. Opciones no marcadas = 0.
A5: Advertencia psicométrica | B5: La puntuación es ipsativa: compara preferencias de la persona consigo misma. No debe interpretarse como porcentaje absoluto de personalidad ni usarse como criterio único de selección.
A6: Estructura del reporte | B6: 4 categorías ejecutivas: Perfil de trabajo, Motivación y compromiso, Gestión directa del jefe, Dinámica de equipo.
A7: Uso recomendado | B7: El jefe debe usar el resultado para adaptar comunicación, delegación, seguimiento, feedback y asignación de roles, no para etiquetar o limitar a las personas.
A8: Hojas incluidas | B8: 01_Items_Clave, 02_Entrada_Respuestas, 03_Scoring, 04_Datos_Graficos, 05_Rubrica, 06_Reglas_Puntaje, 07_Textos_Perfiles, 08_Dashboard_Ejemplo.

Sheet 01_Items_Clave
A1: Item | B1: Módulo | C1: Categoría | D1: Enunciado | E1: Opción A | F1: DISC A | G1: Opción B | H1: DISC B | I1: Opción C | J1: DISC C | K1: Opción D | L1: DISC D
A2: 1 | B2: Orientación general de trabajo | C2: Perfil de trabajo | D2: Cuando participo en un equipo de trabajo, tiendo a: | E2: Impulsar al grupo para avanzar y lograr resultados concretos. | F2: D | G2: Generar entusiasmo y mantener una actitud positiva entre las personas. | H2: I | I2: Apoyar a otros para que el trabajo fluya de manera colaborativa. | J2: S | K2: Cuidar que el trabajo se haga con orden, precisión y calidad. | L2: C
A3: 2 | B3: Orientación general de trabajo | C3: Perfil de trabajo | D3: Cuando recibo una tarea nueva, normalmente prefiero: | E3: Revisar la información disponible antes de definir cómo proceder. | F3: C | G3: Asegurarme de que todos estén alineados y se sientan apoyados. | H3: S | I3: Conversar con otros para conectar ideas y generar energía alrededor de la tarea. | J3: I | K3: Entender el objetivo y comenzar a actuar rápidamente. | L3: D
A4: 3 | B4: Orientación general de trabajo | C4: Perfil de trabajo | D4: En el desarrollo de un proyecto, suelo aportar más cuando: | E4: Hay metas exigentes que requieren decisión y empuje. | F4: D | G4: Se necesita comunicar, motivar o involucrar a otras personas. | H4: I | I4: Es necesario analizar detalles, riesgos o estándares de calidad. | J4: C | K4: Se requiere cooperación, paciencia y apoyo constante. | L4: S
A5: 4 | B5: Orientación general de trabajo | C5: Perfil de trabajo | D5: En mi forma habitual de trabajar, me identifico más con: | E5: Mantener la estabilidad, la colaboración y el buen ambiente. | F5: S | G5: Trabajar con método, exactitud y criterios claros. | H5: C | I5: Crear buenas relaciones y movilizar a otros con entusiasmo. | J5: I | K5: Enfocarme en lograr resultados y superar obstáculos. | L5: D
A6: 5 | B6: Toma de decisiones | C6: Perfil de trabajo | D6: Cuando debo tomar una decisión importante, tiendo a: | E6: Avanzar con rapidez y asumir la responsabilidad del resultado. | F6: D | G6: Conversar con otros para generar apoyo y compromiso. | H6: I | I6: Considerar cómo la decisión afectará al equipo. | J6: S | K6: Revisar datos, criterios y posibles riesgos antes de actuar. | L6: C
A7: 6 | B7: Toma de decisiones | C7: Perfil de trabajo | D7: Cuando hay poco tiempo para decidir, normalmente prefiero: | E7: Identificar la información mínima necesaria para reducir errores. | F7: C | G7: Evitar decisiones apresuradas que puedan afectar la estabilidad del equipo. | H7: S | I7: Buscar rápidamente opiniones que ayuden a generar consenso. | J7: I | K7: Tomar una decisión práctica y ajustar sobre la marcha si es necesario. | L7: D
A8: 7 | B8: Toma de decisiones | C8: Perfil de trabajo | D8: Antes de comprometerme con una decisión, suelo darle más importancia a: | E8: Que permita avanzar hacia el objetivo sin perder tiempo. | F8: D | G8: Que las personas involucradas se sientan motivadas y convencidas. | H8: I | I8: Que el equipo pueda adaptarse sin tensiones innecesarias. | J8: S | K8: Que existan fundamentos claros y evidencia suficiente. | L8: C
A9: 8 | B9: Toma de decisiones | C9: Perfil de trabajo | D9: Cuando el equipo no logra decidir, mi tendencia natural es: | E9: Ordenar la información y establecer criterios para decidir mejor. | F9: C | G9: Escuchar las posiciones y buscar una salida aceptable para todos. | H9: S | I9: Proponer una dirección clara y empujar la decisión. | J9: D | K9: Animar la conversación para que las personas se involucren. | L9: I
A10: 9 | B10: Comunicación | C10: Gestión directa del jefe | D10: Cuando comunico una idea en el trabajo, tiendo a: | E10: Ir directo al punto y enfocarme en lo que se debe lograr. | F10: D | G10: Expresarla con entusiasmo para captar el interés de los demás. | H10: I | I10: Cuidar el tono para que las personas se sientan escuchadas. | J10: S | K10: Presentarla de forma ordenada, con datos y argumentos claros. | L10: C
A11: 10 | B11: Comunicación | C11: Gestión directa del jefe | D11: Cuando necesito recibir información para hacer mi trabajo, prefiero que me la entreguen: | E11: Con suficiente contexto para entender el impacto en las personas. | F11: S | G11: De forma detallada, precisa y bien estructurada. | H11: C | I11: En una conversación dinámica donde pueda intercambiar ideas. | J11: I | K11: De manera breve, clara y enfocada en la acción esperada. | L11: D
A12: 11 | B12: Comunicación | C12: Gestión directa del jefe | D12: En una reunión de equipo, normalmente tiendo a: | E12: Orientar la conversación hacia decisiones y próximos pasos. | F12: D | G12: Participar activamente, aportar ideas y animar el ambiente. | H12: I | I12: Escuchar con atención y facilitar que todos puedan expresarse. | J12: S | K12: Ordenar los puntos tratados y precisar acuerdos o inconsistencias. | L12: C
A13: 12 | B13: Comunicación | C13: Gestión directa del jefe | D13: Cuando hay un malentendido en el trabajo, suelo: | E13: Revisar los hechos para identificar dónde se produjo la confusión. | F13: C | G13: Escuchar con calma las distintas versiones antes de responder. | H13: S | I13: Conversar con las personas para recuperar apertura y confianza. | J13: I | K13: Aclarar rápidamente qué se espera y cómo avanzar. | L13: D
... A33: 32 | B33: Rol natural en el equipo | C33: Dinámica de equipo | D33: El equipo suele beneficiarse más de mí cuando: | E33: Se requiere rigor, análisis y cuidado por los detalles importantes. | F33: C | G33: Es necesario fortalecer la confianza, la escucha y la colaboración. | H33: S | I33: Hace falta determinación para cerrar temas y superar obstáculos. | J33: D | K33: Se necesita energía positiva para movilizar y mantener motivadas a las personas. | L33: I

Sheet Hoja1
N11: RAFAEL ENRIQUE VELANDIA OBANDO | P11: 1-2026-7543 | Q11: Prueba prog.

Sheet 02_Entrada_Respuestas
A1: ID | B1: Nombre | C1: Equipo | D1: Fecha_aplicación | E1: I1_MÁS | F1: I2_MÁS | G1: I3_MÁS | H1: I4_MÁS | I1: I5_MÁS | J1: I6_MÁS | K1: I7_MÁS | L1: I8_MÁS | M1: I9_MÁS | N1: I10_MÁS | O1: I11_MÁS | P1: I12_MÁS | Q1: I13_MÁS | R1: I14_MÁS | S1: I15_MÁS | T1: I16_MÁS | U1: I17_MÁS | V1: I18_MÁS | W1: I19_MÁS | X1: I20_MÁS | Y1: I21_MÁS | Z1: I22_MÁS | AA1: I23_MÁS | AB1: I24_MÁS | AC1: I25_MÁS | AD1: I26_MÁS | AE1: I27_MÁS | AF1: I28_MÁS | AG1: I29_MÁS | AH1: I30_MÁS | AI1: I31_MÁS | AJ1: I32_MÁS | AK1: I1_MENOS | AL1: I2_MENOS | AM1: I3_MENOS | AN1: I4_MENOS | AO1: I5_MENOS | AP1: I6_MENOS | AQ1: I7_MENOS | AR1: I8_MENOS | AS1: I9_MENOS | AT1: I10_MENOS | AU1: I11_MENOS | AV1: I12_MENOS | AW1: I13_MENOS | AX1: I14_MENOS | AY1: I15_MENOS | AZ1: I16_MENOS | BA1: I17_MENOS | BB1: I18_MENOS | BC1: I19_MENOS | BD1: I20_MENOS | BE1: I21_MENOS | BF1: I22_MENOS | BG1: I23_MENOS | BH1: I24_MENOS | BI1: I25_MENOS | BJ1: I26_MENOS | BK1: I27_MENOS | BL1: I28_MENOS | BM1: I29_MENOS | BN1: I30_MENOS | BO1: I31_MENOS | BP1: I32_MENOS | BQ1: Errores_Misma_Opción
A2: P001 | B2: Ejemplo de funcionario | C2: Equipo A | D2: 46162.887 | E2: A | F2: A | G2: D | H2: A | I2: A | J2: D | K2: A | L2: A | M2: D | N2: D | O2: A | P2: D | Q2: A | R2: A | S2: A | T2: A | U2: A | V2: D | W2: A | X2: D | Y2: A | Z2: D | AA2: A | AB2: D | AC2: A | AD2: D | AE2: A | AF2: D | AG2: A | AH2: D | AI2: A | AJ2: D | AK2: C | AL2: B | AM2: C | AN2: B | AO2: B | AP2: C | AQ2: B | AR2: C | AS2: B | AT2: B | AU2: C | AV2: B | AW2: C | AX2: C | AY2: C | AZ2: B | BA2: B | BB2: C | BC2: C | BD2: B | BE2: B | BF2: C | BG2: C | BH2: B | BI2: B | BJ2: C | BK2: C | BL2: B | BM2: B | BN2: C | BO2: C | BP2: B | BQ2: =SUM(--(E2=AK2),--(F2=AL2),--(G2=AM2),--(H2=AN2),--(I2=AO2),--(J2=AP2),--(K2=AQ2),--(L2=AR2),--(M2=AS2),--(N2=AT2),--(O2=AU2),--(P2=AV2),--(Q2=AW2),--(R2=AX2),--(S2=AY2),--(T2=AZ2),--(U2=BA2),--(V2=BB2),--(W2=BC2),--(X2=BD2),--(Y2=BE2),--(Z2=BF2),--(AA2=BG2),--(AB2=BH2),--(AC2=BI2),--(AD2=BJ2),--(AE2=BK2),--(AF2=BL2),--(AG2=BM2),--(AH2=BN2),--(AI2=BO2),--(AJ2=BP2)) -> 0
BQ3: =SUM(--(E3=AK3),--(F3=AL3),--(G3=AM3),--(H3=AN3),--(I3=AO3),--(J3=AP3),--(K3=AQ3),--(L3=AR3),--(M3=AS3),--(N3=AT3),--(O3=AU3),--(P3=AV3),--(Q3=AW3),--(R3=AX3),--(S3=AY3),--(T3=AZ3),--(U3=BA3),--(V3=BB3),--(W3=BC3),--(X3=BD3),--(Y3=BE3),--(Z3=BF3),--(AA3=BG3),--(AB3=BH3),--(AC3=BI3),--(AD3=BJ3),--(AE3=BK3),--(AF3=BL3),--(AG3=BM3),--(AH3=BN3),--(AI3=BO3),--(AJ3=BP3)) -> 32
BQ4: =SUM(--(E4=AK4),--(F4=AL4),--(G4=AM4),--(H4=AN4),--(I4=AO4),--(J4=AP4),--(K4=AQ4),--(L4=AR4),--(M4=AS4),--(N4=AT4),--(O4=AU4),--(P4=AV4),--(Q4=AW4),--(R4=AX4),--(S4=AY4),--(T4=AZ4),--(U4=BA4),--(V4=BB4),--(W4=BC4),--(X4=BD4),--(Y4=BE4),--(Z4=BF4),--(AA4=BG4),--(AB4=BH4),--(AC4=BI4),--(AD4=BJ4),--(AE4=BK4),--(AF4=BL4),--(AG4=BM4),--(AH4=BN4),--(AI4=BO4),--(AJ4=BP4)) -> 32
BQ5: =SUM(--(E5=AK5),--(F5=AL5),--(G5=AM5),--(H5=AN5),--(I5=AO5),--(J5=AP5),--(K5=AQ5),--(L5=AR5),--(M5=AS5),--(N5=AT5),--(O5=AU5),--(P5=AV5),--(Q5=AW5),--(R5=AX5),--(S5=AY5),--(T5=AZ5),--(U5=BA5),--(V5=BB5),--(W5=BC5),--(X5=BD5),--(Y5=BE5),--(Z5=BF5),--(AA5=BG5),--(AB5=BH5),--(AC5=BI5),--(AD5=BJ5),--(AE5=BK5),--(AF5=BL5),--(AG5=BM5),--(AH5=BN5),--(AI5=BO5),--(AJ5=BP5)) -> 32
BQ6: =SUM(--(E6=AK6),--(F6=AL6),--(G6=AM6),--(H6=AN6),--(I6=AO6),--(J6=AP6),--(K6=AQ6),--(L6=AR6),--(M6=AS6),--(N6=AT6),--(O6=AU6),--(P6=AV6),--(Q6=AW6),--(R6=AX6),--(S6=AY6),--(T6=AZ6),--(U6=BA6),--(V6=BB6),--(W6=BC6),--(X6=BD6),--(Y6=BE6),--(Z6=BF6),--(AA6=BG6),--(AB6=BH6),--(AC6=BI6),--(AD6=BJ6),--(AE6=BK6),--(AF6=BL6),--(AG6=BM6),--(AH6=BN6),--(AI6=BO6),--(AJ6=BP6)) -> 32
BQ7: =SUM(--(E7=AK7),--(F7=AL7),--(G7=AM7),--(H7=AN7),--(I7=AO7),--(J7=AP7),--(K7=AQ7),--(L7=AR7),--(M7=AS7),--(N7=AT7),--(O7=AU7),--(P7=AV7),--(Q7=AW7),--(R7=AX7),--(S7=AY7),--(T7=AZ7),--(U7=BA7),--(V7=BB7),--(W7=BC7),--(X7=BD7),--(Y7=BE7),--(Z7=BF7),--(AA7=BG7),--(AB7=BH7),--(AC7=BI7),--(AD7=BJ7),--(AE7=BK7),--(AF7=BL7),--(AG7=BM7),--(AH7=BN7),--(AI7=BO7),--(AJ7=BP7)) -> 32
BQ8: =SUM(--(E8=AK8),--(F8=AL8),--(G8=AM8),--(H8=AN8),--(I8=AO8),--(J8=AP8),--(K8=AQ8),--(L8=AR8),--(M8=AS8),--(N8=AT8),--(O8=AU8),--(P8=AV8),--(Q8=AW8),--(R8=AX8),--(S8=AY8),--(T8=AZ8),--(U8=BA8),--(V8=BB8),--(W8=BC8),--(X8=BD8),--(Y8=BE8),--(Z8=BF8),--(AA8=BG8),--(AB8=BH8),--(AC8=BI8),--(AD8=BJ8),--(AE8=BK8),--(AF8=BL8),--(AG8=BM8),--(AH8=BN8),--(AI8=BO8),--(AJ8=BP8)) -> 32
BQ9: =SUM(--(E9=AK9),--(F9=AL9),--(G9=AM9),--(H9=AN9),--(I9=AO9),--(J9=AP9),--(K9=AQ9),--(L9=AR9),--(M9=AS9),--(N9=AT9),--(O9=AU9),--(P9=AV9),--(Q9=AW9),--(R9=AX9),--(S9=AY9),--(T9=AZ9),--(U9=BA9),--(V9=BB9),--(W9=BC9),--(X9=BD9),--(Y9=BE9),--(Z9=BF9),--(AA9=BG9),--(AB9=BH9),--(AC9=BI9),--(AD9=BJ9),--(AE9=BK9),--(AF9=BL9),--(AG9=BM9),--(AH9=BN9),--(AI9=BO9),--(AJ9=BP9)) -> 32
BQ10: =SUM(--(E10=AK10),--(F10=AL10),--(G10=AM10),--(H10=AN10),--(I10=AO10),--(J10=AP10),--(K10=AQ10),--(L10=AR10),--(M10=AS10),--(N10=AT10),--(O10=AU10),--(P10=AV10),--(Q10=AW10),--(R10=AX10),--(S10=AY10),--(T10=AZ10),--(U10=BA10),--(V10=BB10),--(W10=BC10),--(X10=BD10),--(Y10=BE10),--(Z10=BF10),--(AA10=BG10),--(AB10=BH10),--(AC10=BI10),--(AD10=BJ10),--(AE10=BK10),--(AF10=BL10),--(AG10=BM10),--(AH10=BN10),--(AI10=BO10),--(AJ10=BP10)) -> 32
BQ11: =SUM(--(E11=AK11),--(F11=AL11),--(G11=AM11),--(H11=AN11),--(I11=AO11),--(J11=AP11),--(K11=AQ11),--(L11=AR11),--(M11=AS11),--(N11=AT11),--(O11=AU11),--(P11=AV11),--(Q11=AW11),--(R11=AX11),--(S11=AY11),--(T11=AZ11),--(U11=BA11),--(V11=BB11),--(W11=BC11),--(X11=BD11),--(Y11=BE11),--(Z11=BF11),--(AA11=BG11),--(AB11=BH11),--(AC11=BI11),--(AD11=BJ11),--(AE11=BK11),--(AF11=BL11),--(AG11=BM11),--(AH11=BN11),--(AI11=BO11),--(AJ11=BP11)) -> 32
BQ12: =SUM(--(E12=AK12),--(F12=AL12),--(G12=AM12),--(H12=AN12),--(I12=AO12),--(J12=AP12),--(K12=AQ12),--(L12=AR12),--(M12=AS12),--(N12=AT12),--(O12=AU12),--(P12=AV12),--(Q12=AW12),--(R12=AX12),--(S12=AY12),--(T12=AZ12),--(U12=BA12),--(V12=BB12),--(W12=BC12),--(X12=BD12),--(Y12=BE12),--(Z12=BF12),--(AA12=BG12),--(AB12=BH12),--(AC12=BI12),--(AD12=BJ12),--(AE12=BK12),--(AF12=BL12),--(AG12=BM12),--(AH12=BN12),--(AI12=BO12),--(AJ12=BP12)) -> 32
BQ13: =SUM(--(E13=AK13),--(F13=AL13),--(G13=AM13),--(H13=AN13),--(I13=AO13),--(J13=AP13),--(K13=AQ13),--(L13=AR13),--(M13=AS13),--(N13=AT13),--(O13=AU13),--(P13=AV13),--(Q13=AW13),--(R13=AX13),--(S13=AY13),--(T13=AZ13),--(U13=BA13),--(V13=BB13),--(W13=BC13),--(X13=BD13),--(Y13=BE13),--(Z13=BF13),--(AA13=BG13),--(AB13=BH13),--(AC13=BI13),--(AD13=BJ13),--(AE13=BK13),--(AF13=BL13),--(AG13=BM13),--(AH13=BN13),--(AI13=BO13),--(AJ13=BP13)) -> 32
BQ14: =SUM(--(E14=AK14),--(F14=AL14),--(G14=AM14),--(H14=AN14),--(I14=AO14),--(J14=AP14),--(K14=AQ14),--(L14=AR14),--(M14=AS14),--(N14=AT14),--(O14=AU14),--(P14=AV14),--(Q14=AW14),--(R14=AX14),--(S14=AY14),--(T14=AZ14),--(U14=BA14),--(V14=BB14),--(W14=BC14),--(X14=BD14),--(Y14=BE14),--(Z14=BF14),--(AA14=BG14),--(AB14=BH14),--(AC14=BI14),--(AD14=BJ14),--(AE14=BK14),--(AF14=BL14),--(AG14=BM14),--(AH14=BN14),--(AI14=BO14),--(AJ14=BP14)) -> 32
... BQ101: =SUM(--(E101=AK101),--(F101=AL101),--(G101=AM101),--(H101=AN101),--(I101=AO101),--(J101=AP101),--(K101=AQ101),--(L101=AR101),--(M101=AS101),--(N101=AT101),--(O101=AU101),--(P101=AV101),--(Q101=AW101),--(R101=AX101),--(S101=AY101),--(T101=AZ101),--(U101=BA101),--(V101=BB101),--(W101=BC101),--(X101=BD101),--(Y101=BE101),--(Z101=BF101),--(AA101=BG101),--(AB101=BH101),--(AC101=BI101),--(AD101=BJ101),--(AE101=BK101),--(AF101=BL101),--(AG101=BM101),--(AH101=BN101),--(AI101=BO101),--(AJ101=BP101)) -> 32

Sheet 03_Scoring
A1: ID | B1: Nombre | C1: Equipo | D1: D_Global | E1: I_Global | F1: S_Global | G1: C_Global | H1: Estilo_Principal | I1: Puntaje_Principal | J1: Estilo_Secundario | K1: Puntaje_Secundario | L1: Perfil_Combinado | M1: Perfil_de_trabajo_D | N1: Perfil_de_trabajo_I | O1: Perfil_de_trabajo_S | P1: Perfil_de_trabajo_C | Q1: Perfil_de_trabajo_Dominante | R1: Perfil_de_trabajo_Puntaje | S1: Perfil_de_trabajo_Nivel | T1: Motivacion_compromiso_D | U1: Motivacion_compromiso_I | V1: Motivacion_compromiso_S | W1: Motivacion_compromiso_C | X1: Motivacion_compromiso_Dominante | Y1: Motivacion_compromiso_Puntaje | Z1: Motivacion_compromiso_Nivel | AA1: Gestion_directa_del_jefe_D | AB1: Gestion_directa_del_jefe_I | AC1: Gestion_directa_del_jefe_S | AD1: Gestion_directa_del_jefe_C | AE1: Gestion_directa_del_jefe_Dominante | AF1: Gestion_directa_del_jefe_Puntaje | AG1: Gestion_directa_del_jefe_Nivel | AH1: Dinamica_de_equipo_D | AI1: Dinamica_de_equipo_I | AJ1: Dinamica_de_equipo_S | AK1: Dinamica_de_equipo_C | AL1: Dinamica_de_equipo_Dominante | AM1: Dinamica_de_equipo_Puntaje | AN1: Dinamica_de_equipo_Nivel
A2: ='02_Entrada_Respuestas'!A2 -> P001 | B2: ='02_Entrada_Respuestas'!B2 -> Ejemplo de funcionario | C2: ='02_Entrada_Respuestas'!C2 -> Equipo A | D2: =(COUNTIF('02_Entrada_Respuestas'!E2:AJ2,"A"))-(COUNTIF('02_Entrada_Respuestas'!AK2:BP2,"A")) -> 19 | E2: =(COUNTIF('02_Entrada_Respuestas'!E2:AJ2,"B"))-(COUNTIF('02_Entrada_Respuestas'!AK2:BP2,"B")) -> -16 | F2: =(COUNTIF('02_Entrada_Respuestas'!E2:AJ2,"C"))-(COUNTIF('02_Entrada_Respuestas'!AK2:BP2,"C")) -> -16 | G2: =(COUNTIF('02_Entrada_Respuestas'!E2:AJ2,"D"))-(COUNTIF('02_Entrada_Respuestas'!AK2:BP2,"D")) -> 13 | H2: =LEFT(INDEX($D$1:$G$1,1,MATCH(MAX(D2:G2),D2:G2,0)),1) -> D | I2: =MAX(D2:G2) -> 19 | J2: =LEFT(INDEX($D$1:$G$1,1,MATCH(LARGE(D2:G2,2),D2:G2,0)),1) -> C | K2: =LARGE(D2:G2,2) -> 13 | L2: =H2&"/"&J2 -> D/C | M2: =(COUNTIF('02_Entrada_Respuestas'!E2:L2,"A"))-(COUNTIF('02_Entrada_Respuestas'!AK2:AR2,"A")) -> 6 | N2: =(COUNTIF('02_Entrada_Respuestas'!E2:L2,"B"))-(COUNTIF('02_Entrada_Respuestas'!AK2:AR2,"B")) -> -4 | O2: =(COUNTIF('02_Entrada_Respuestas'!E2:L2,"C"))-(COUNTIF('02_Entrada_Respuestas'!AK2:AR2,"C")) -> -4 | P2: =(COUNTIF('02_Entrada_Respuestas'!E2:L2,"D"))-(COUNTIF('02_Entrada_Respuestas'!AK2:AR2,"D")) -> 2 | Q2: =RIGHT(INDEX(M$1:P$1,1,MATCH(MAX(M2:P2),M2:P2,0)),1) -> D | R2: =MAX(M2:P2) -> 6 | S2: =IF(MAX(M2:P2)>=8*0.5,"Alto",IF(MAX(M2:P2)>=8*0.15,"Medio","Mixto/Neutro")) -> Alto | T2: =(COUNTIF('02_Entrada_Respuestas'!Q2:T2,"A"))-(COUNTIF('02_Entrada_Respuestas'!AW2:AZ2,"A")) -> 4 | U2: =(COUNTIF('02_Entrada_Respuestas'!Q2:T2,"B"))-(COUNTIF('02_Entrada_Respuestas'!AW2:AZ2,"B")) -> -1 | V2: =(COUNTIF('02_Entrada_Respuestas'!Q2:T2,"C"))-(COUNTIF('02_Entrada_Respuestas'!AW2:AZ2,"C")) -> -3 | W2: =(COUNTIF('02_Entrada_Respuestas'!Q2:T2,"D"))-(COUNTIF('02_Entrada_Respuestas'!AW2:AZ2,"D")) -> 0 | X2: =RIGHT(INDEX(T$1:W$1,1,MATCH(MAX(T2:W2),T2:W2,0)),1) -> D | Y2: =MAX(T2:W2) -> 4 | Z2: =IF(MAX(T2:W2)>=4*0.5,"Alto",IF(MAX(T2:W2)>=4*0.15,"Medio","Mixto/Neutro")) -> Alto | AA2: =(COUNTIF('02_Entrada_Respuestas'!M2:P2,"A")+COUNTIF('02_Entrada_Respuestas'!U2:AB2,"A"))-(COUNTIF('02_Entrada_Respuestas'!AS2:AV2,"A")+COUNTIF('02_Entrada_Respuestas'!BA2:BH2,"A")) -> 5 | AB2: =(COUNTIF('02_Entrada_Respuestas'!M2:P2,"B")+COUNTIF('02_Entrada_Respuestas'!U2:AB2,"B"))-(COUNTIF('02_Entrada_Respuestas'!AS2:AV2,"B")+COUNTIF('02_Entrada_Respuestas'!BA2:BH2,"B")) -> -7 | AC2: =(COUNTIF('02_Entrada_Respuestas'!M2:P2,"C")+COUNTIF('02_Entrada_Respuestas'!U2:AB2,"C"))-(COUNTIF('02_Entrada_Respuestas'!AS2:AV2,"C")+COUNTIF('02_Entrada_Respuestas'!BA2:BH2,"C")) -> -5 | AD2: =(COUNTIF('02_Entrada_Respuestas'!M2:P2,"D")+COUNTIF('02_Entrada_Respuestas'!U2:AB2,"D"))-(COUNTIF('02_Entrada_Respuestas'!AS2:AV2,"D")+COUNTIF('02_Entrada_Respuestas'!BA2:BH2,"D")) -> 7 | AE2: =RIGHT(INDEX(AA$1:AD$1,1,MATCH(MAX(AA2:AD2),AA2:AD2,0)),1) -> C | AF2: =MAX(AA2:AD2) -> 7 | AG2: =IF(MAX(AA2:AD2)>=12*0.5,"Alto",IF(MAX(AA2:AD2)>=12*0.15,"Medio","Mixto/Neutro")) -> Alto | AH2: =(COUNTIF('02_Entrada_Respuestas'!AC2:AJ2,"A"))-(COUNTIF('02_Entrada_Respuestas'!BI2:BP2,"A")) -> 4 | AI2: =(COUNTIF('02_Entrada_Respuestas'!AC2:AJ2,"B"))-(COUNTIF('02_Entrada_Respuestas'!BI2:BP2,"B")) -> -4 | AJ2: =(COUNTIF('02_Entrada_Respuestas'!AC2:AJ2,"C"))-(COUNTIF('02_Entrada_Respuestas'!BI2:BP2,"C")) -> -4 | AK2: =(COUNTIF('02_Entrada_Respuestas'!AC2:AJ2,"D"))-(COUNTIF('02_Entrada_Respuestas'!BI2:BP2,"D")) -> 4 | AL2: =RIGHT(INDEX(AH$1:AK$1,1,MATCH(MAX(AH2:AK2),AH2:AK2,0)),1) -> D | AM2: =MAX(AH2:AK2) -> 4 | AN2: =IF(MAX(AH2:AK2)>=8*0.5,"Alto",IF(MAX(AH2:AK2)>=8*0.15,"Medio","Mixto/Neutro")) -> Alto
A3: ='02_Entrada_Respuestas'!A3 -> 0 | B3: ='02_Entrada_Respuestas'!B3 -> 0 | C3: ='02_Entrada_Respuestas'!C3 -> 0 | D3: =(COUNTIF('02_Entrada_Respuestas'!E3:AJ3,"A"))-(COUNTIF('02_Entrada_Respuestas'!AK3:BP3,"A")) -> 0 | E3: =(COUNTIF('02_Entrada_Respuestas'!E3:AJ3,"B"))-(COUNTIF('02_Entrada_Respuestas'!AK3:BP3,"B")) -> 0 | F3: =(COUNTIF('02_Entrada_Respuestas'!E3:AJ3,"C"))-(COUNTIF('02_Entrada_Respuestas'!AK3:BP3,"C")) -> 0 | G3: =(COUNTIF('02_Entrada_Respuestas'!E3:AJ3,"D"))-(COUNTIF('02_Entrada_Respuestas'!AK3:BP3,"D")) -> 0 | H3: =LEFT(INDEX($D$1:$G$1,1,MATCH(MAX(D3:G3),D3:G3,0)),1) -> D | I3: =MAX(D3:G3) -> 0 | J3: =LEFT(INDEX($D$1:$G$1,1,MATCH(LARGE(D3:G3,2),D3:G3,0)),1) -> D | K3: =LARGE(D3:G3,2) -> 0 | L3: =H3&"/"&J3 -> D/D | M3: =(COUNTIF('02_Entrada_Respuestas'!E3:L3,"A"))-(COUNTIF('02_Entrada_Respuestas'!AK3:AR3,"A")) -> 0 | N3: =(COUNTIF('02_Entrada_Respuestas'!E3:L3,"B"))-(COUNTIF('02_Entrada_Respuestas'!AK3:AR3,"B")) -> 0 | O3: =(COUNTIF('02_Entrada_Respuestas'!E3:L3,"C"))-(COUNTIF('02_Entrada_Respuestas'!AK3:AR3,"C")) -> 0 | P3: =(COUNTIF('02_Entrada_Respuestas'!E3:L3,"D"))-(COUNTIF('02_Entrada_Respuestas'!AK3:AR3,"D")) -> 0 | Q3: =RIGHT(INDEX(M$1:P$1,1,MATCH(MAX(M3:P3),M3:P3,0)),1) -> D | R3: =MAX(M3:P3) -> 0 | S3: =IF(MAX(M3:P3)>=8*0.5,"Alto",IF(MAX(M3:P3)>=8*0.15,"Medio","Mixto/Neutro")) -> Mixto/Neutro | T3: =(COUNTIF('02_Entrada_Respuestas'!Q3:T3,"A"))-(COUNTIF('02_Entrada_Respuestas'!AW3:AZ3,"A")) -> 0 | U3: =(COUNTIF('02_Entrada_Respuestas'!Q3:T3,"B"))-(COUNTIF('02_Entrada_Respuestas'!AW3:AZ3,"B")) -> 0 | V3: =(COUNTIF('02_Entrada_Respuestas'!Q3:T3,"C"))-(COUNTIF('02_Entrada_Respuestas'!AW3:AZ3,"C")) -> 0 | W3: =(COUNTIF('02_Entrada_Respuestas'!Q3:T3,"D"))-(COUNTIF('02_Entrada_Respuestas'!AW3:AZ3,"D")) -> 0 | X3: =RIGHT(INDEX(T$1:W$1,1,MATCH(MAX(T3:W3),T3:W3,0)),1) -> D | Y3: =MAX(T3:W3) -> 0 | Z3: =IF(MAX(T3:W3)>=4*0.5,"Alto",IF(MAX(T3:W3)>=4*0.15,"Medio","Mixto/Neutro")) -> Mixto/Neutro | AA3: =(COUNTIF('02_Entrada_Respuestas'!M3:P3,"A")+COUNTIF('02_Entrada_Respuestas'!U3:AB3,"A"))-(COUNTIF('02_Entrada_Respuestas'!AS3:AV3,"A")+COUNTIF('02_Entrada_Respuestas'!BA3:BH3,"A")) -> 0 | AB3: =(COUNTIF('02_Entrada_Respuestas'!M3:P3,"B")+COUNTIF('02_Entrada_Respuestas'!U3:AB3,"B"))-(COUNTIF('02_Entrada_Respuestas'!AS3:AV3,"B")+COUNTIF('02_Entrada_Respuestas'!BA3:BH3,"B")) -> 0 | AC3: =(COUNTIF('02_Entrada_Respuestas'!M3:P3,"C")+COUNTIF('02_Entrada_Respuestas'!U3:AB3,"C"))-(COUNTIF('02_Entrada_Respuestas'!AS3:AV3,"C")+COUNTIF('02_Entrada_Respuestas'!BA3:BH3,"C")) -> 0 | AD3: =(COUNTIF('02_Entrada_Respuestas'!M3:P3,"D")+COUNTIF('02_Entrada_Respuestas'!U3:AB3,"D"))-(COUNTIF('02_Entrada_Respuestas'!AS3:AV3,"D")+COUNTIF('02_Entrada_Respuestas'!BA3:BH3,"D")) -> 0 | AE3: =RIGHT(INDEX(AA$1:AD$1,1,MATCH(MAX(AA3:AD3),AA3:AD3,0)),1) -> D | AF3: =MAX(AA3:AD3) -> 0 | AG3: =IF(MAX(AA3:AD3)>=12*0.5,"Alto",IF(MAX(AA3:AD3)>=12*0.15,"Medio","Mixto/Neutro")) -> Mixto/Neutro | AH3: =(COUNTIF('02_Entrada_Respuestas'!AC3:AJ3,"A"))-(COUNTIF('02_Entrada_Respuestas'!BI3:BP3,"A")) -> 0 | AI3: =(COUNTIF('02_Entrada_Respuestas'!AC3:AJ3,"B"))-(COUNTIF('02_Entrada_Respuestas'!BI3:BP3,"B")) -> 0 | AJ3: =(COUNTIF('02_Entrada_Respuestas'!AC3:AJ3,"C"))-(COUNTIF('02_Entrada_Respuestas'!BI3:BP3,"C")) -> 0 | AK3: =(COUNTIF('02_Entrada_Respuestas'!AC3:AJ3,"D"))-(COUNTIF('02_Entrada_Respuestas'!BI3:BP3,"D")) -> 0 | AL3: =RIGHT(INDEX(AH$1:AK$1,1,MATCH(MAX(AH3:AK3),AH3:AK3,0)),1) -> D | AM3: =MAX(AH3:AK3) -> 0 | AN3: =IF(MAX(AH3:AK3)>=8*0.5,"Alto",IF(MAX(AH3:AK3)>=8*0.15,"Medio","Mixto/Neutro")) -> Mixto/Neutro
A4: ='02_Entrada_Respuestas'!A4 -> 0 | B4: ='02_Entrada_Respuestas'!B4 -> 0 | C4: ='02_Entrada_Respuestas'!C4 -> 0 | D4: =(COUNTIF('02_Entrada_Respuestas'!E4:AJ4,"A"))-(COUNTIF('02_Entrada_Respuestas'!AK4:BP4,"A")) -> 0 | E4: =(COUNTIF('02_Entrada_Respuestas'!E4:AJ4,"B"))-(COUNTIF('02_Entrada_Respuestas'!AK4:BP4,"B")) -> 0 | F4: =(COUNTIF('02_Entrada_Respuestas'!E4:AJ4,"C"))-(COUNTIF('02_Entrada_Respuestas'!AK4:BP4,"C")) -> 0 | G4: =(COUNTIF('02_Entrada_Respuestas'!E4:AJ4,"D"))-(COUNTIF('02_Entrada_Respuestas'!AK4:BP4,"D")) -> 0 | H4: =LEFT(INDEX($D$1:$G$1,1,MATCH(MAX(D4:G4),D4:G4,0)),1) -> D | I4: =MAX(D4:G4) -> 0 | J4: =LEFT(INDEX($D$1:$G$1,1,MATCH(LARGE(D4:G4,2),D4:G4,0)),1) -> D | K4: =LARGE(D4:G4,2) -> 0 | L4: =H4&"/"&J4 -> D/D | M4: =(COUNTIF('02_Entrada_Respuestas'!E4:L4,"A"))-(COUNTIF('02_Entrada_Respuestas'!AK4:AR4,"A")) -> 0 | N4: =(COUNTIF('02_Entrada_Respuestas'!E4:L4,"B"))-(COUNTIF('02_Entrada_Respuestas'!AK4:AR4,"B")) -> 0 | O4: =(COUNTIF('02_Entrada_Respuestas'!E4:L4,"C"))-(COUNTIF('02_Entrada_Respuestas'!AK4:AR4,"C")) -> 0 | P4: =(COUNTIF('02_Entrada_Respuestas'!E4:L4,"D"))-(COUNTIF('02_Entrada_Respuestas'!AK4:AR4,"D")) -> 0 | Q4: =RIGHT(INDEX(M$1:P$1,1,MATCH(MAX(M4:P4),M4:P4,0)),1) -> D | R4: =MAX(M4:P4) -> 0 | S4: =IF(MAX(M4:P4)>=8*0.5,"Alto",IF(MAX(M4:P4)>=8*0.15,"Medio","Mixto/Neutro")) -> Mixto/Neutro | T4: =(COUNTIF('02_Entrada_Respuestas'!Q4:T4,"A"))-(COUNTIF('02_Entrada_Respuestas'!AW4:AZ4,"A")) -> 0 | U4: =(COUNTIF('02_Entrada_Respuestas'!Q4:T4,"B"))-(COUNTIF('02_Entrada_Respuestas'!AW4:AZ4,"B")) -> 0 | V4: =(COUNTIF('02_Entrada_Respuestas'!Q4:T4,"C"))-(COUNTIF('02_Entrada_Respuestas'!AW4:AZ4,"C")) -> 0 | W4: =(COUNTIF('02_Entrada_Respuestas'!Q4:T4,"D"))-(COUNTIF('02_Entrada_Respuestas'!AW4:AZ4,"D")) -> 0 | X4: =RIGHT(INDEX(T$1:W$1,1,MATCH(MAX(T4:W4),T4:W4,0)),1) -> D | Y4: =MAX(T4:W4) -> 0 | Z4: =IF(MAX(T4:W4)>=4*0.5,"Alto",IF(MAX(T4:W4)>=4*0.15,"Medio","Mixto/Neutro")) -> Mixto/Neutro | AA4: =(COUNTIF('02_Entrada_Respuestas'!M4:P4,"A")+COUNTIF('02_Entrada_Respuestas'!U4:AB4,"A"))-(COUNTIF('02_Entrada_Respuestas'!AS4:AV4,"A")+COUNTIF('02_Entrada_Respuestas'!BA4:BH4,"A")) -> 0 | AB4: =(COUNTIF('02_Entrada_Respuestas'!M4:P4,"B")+COUNTIF('02_Entrada_Respuestas'!U4:AB4,"B"))-(COUNTIF('02_Entrada_Respuestas'!AS4:AV4,"B")+COUNTIF('02_Entrada_Respuestas'!BA4:BH4,"B")) -> 0 | AC4: =(COUNTIF('02_Entrada_Respuestas'!M4:P4,"C")+COUNTIF('02_Entrada_Respuestas'!U4:AB4,"C"))-(COUNTIF('02_Entrada_Respuestas'!AS4:AV4,"C")+COUNTIF('02_Entrada_Respuestas'!BA4:BH4,"C")) -> 0 | AD4: =(COUNTIF('02_Entrada_Respuestas'!M4:P4,"D")+COUNTIF('02_Entrada_Respuestas'!U4:AB4,"D"))-(COUNTIF('02_Entrada_Respuestas'!AS4:AV4,"D")+COUNTIF('02_Entrada_Respuestas'!BA4:BH4,"D")) -> 0 | AE4: =RIGHT(INDEX(AA$1:AD$1,1,MATCH(MAX(AA4:AD4),AA4:AD4,0)),1) -> D | AF4: =MAX(AA4:AD4) -> 0 | AG4: =IF(MAX(AA4:AD4)>=12*0.5,"Alto",IF(MAX(AA4:AD4)>=12*0.15,"Medio","Mixto/Neutro")) -> Mixto/Neutro | AH4: =(COUNTIF('02_Entrada_Respuestas'!AC4:AJ4,"A"))-(COUNTIF('02_Entrada_Respuestas'!BI4:BP4,"A")) -> 0 | AI4: =(COUNTIF('02_Entrada_Respuestas'!AC4:AJ4,"B"))-(COUNTIF('02_Entrada_Respuestas'!BI4:BP4,"B")) -> 0 | AJ4: =(COUNTIF('02_Entrada_Respuestas'!AC4:AJ4,"C"))-(COUNTIF('02_Entrada_Respuestas'!BI4:BP4,"C")) -> 0 | AK4: =(COUNTIF('02_Entrada_Respuestas'!AC4:AJ4,"D"))-(COUNTIF('02_Entrada_Respuestas'!BI4:BP4,"D")) -> 0 | AL4: =RIGHT(INDEX(AH$1:AK$1,1,MATCH(MAX(AH4:AK4),AH4:AK4,0)),1) -> D | AM4: =MAX(AH4:AK4) -> 0 | AN4: =IF(MAX(AH4:AK4)>=8*0.5,"Alto",IF(MAX(AH4:AK4)>=8*0.15,"Medio","Mixto/Neutro")) -> Mixto/Neutro
A5: ='02_Entrada_Respuestas'!A5 -> 0 | B5: ='02_Entrada_Respuestas'!B5 -> 0 | C5: ='02_Entrada_Respuestas'!C5 -> 0 | D5: =(COUNTIF('02_Entrada_Respuestas'!E5:AJ5,"A"))-(COUNTIF('02_Entrada_Respuestas'!AK5:BP5,"A")) -> 0 | E5: =(COUNTIF('02_Entrada_Respuestas'!E5:AJ5,"B"))-(COUNTIF('02_Entrada_Respuestas'!AK5:BP5,"B")) -> 0 | F5: =(COUNTIF('02_Entrada_Respuestas'!E5:AJ5,"C"))-(COUNTIF('02_Entrada_Respuestas'!AK5:BP5,"C")) -> 0 | G5: =(COUNTIF('02_Entrada_Respuestas'!E5:AJ5,"D"))-(COUNTIF('02_Entrada_Respuestas'!AK5:BP5,"D")) -> 0 | H5: =LEFT(INDEX($D$1:$G$1,1,MATCH(MAX(D5:G5),D5:G5,0)),1) -> D | I5: =MAX(D5:G5) -> 0 | J5: =LEFT(INDEX($D$1:$G$1,1,MATCH(LARGE(D5:G5,2),D5:G5,0)),1) -> D | K5: =LARGE(D5:G5,2) -> 0 | L5: =H5&"/"&J5 -> D/D | M5: =(COUNTIF('02_Entrada_Respuestas'!E5:L5,"A"))-(COUNTIF('02_Entrada_Respuestas'!AK5:AR5,"A")) -> 0 | N5: =(COUNTIF('02_Entrada_Respuestas'!E5:L5,"B"))-(COUNTIF('02_Entrada_Respuestas'!AK5:AR5,"B")) -> 0 | O5: =(COUNTIF('02_Entrada_Respuestas'!E5:L5,"C"))-(COUNTIF('02_Entrada_Respuestas'!AK5:AR5,"C")) -> 0 | P5: =(COUNTIF('02_Entrada_Respuestas'!E5:L5,"D"))-(COUNTIF('02_Entrada_Respuestas'!AK5:AR5,"D")) -> 0 | Q5: =RIGHT(INDEX(M$1:P$1,1,MATCH(MAX(M5:P5),M5:P5,0)),1) -> D | R5: =MAX(M5:P5) -> 0 | S5: =IF(MAX(M5:P5)>=8*0.5,"Alto",IF(MAX(M5:P5)>=8*0.15,"Medio","Mixto/Neutro")) -> Mixto/Neutro | T5: =(COUNTIF('02_Entrada_Respuestas'!Q5:T5,"A"))-(COUNTIF('02_Entrada_Respuestas'!AW5:AZ5,"A")) -> 0 | U5: =(COUNTIF('02_Entrada_Respuestas'!Q5:T5,"B"))-(COUNTIF('02_Entrada_Respuestas'!AW5:AZ5,"B")) -> 0 | V5: =(COUNTIF('02_Entrada_Respuestas'!Q5:T5,"C"))-(COUNTIF('02_Entrada_Respuestas'!AW5:AZ5,"C")) -> 0 | W5: =(COUNTIF('02_Entrada_Respuestas'!Q5:T5,"D"))-(COUNTIF('02_Entrada_Respuestas'!AW5:AZ5,"D")) -> 0 | X5: =RIGHT(INDEX(T$1:W$1,1,MATCH(MAX(T5:W5),T5:W5,0)),1) -> D | Y5: =MAX(T5:W5) -> 0 | Z5: =IF(MAX(T5:W5)>=4*0.5,"Alto",IF(MAX(T5:W5)>=4*0.15,"Medio","Mixto/Neutro")) -> Mixto/Neutro | AA5: =(COUNTIF('02_Entrada_Respuestas'!M5:P5,"A")+COUNTIF('02_Entrada_Respuestas'!U5:AB5,"A"))-(COUNTIF('02_Entrada_Respuestas'!AS5:AV5,"A")+COUNTIF('02_Entrada_Respuestas'!BA5:BH5,"A")) -> 0 | AB5: =(COUNTIF('02_Entrada_Respuestas'!M5:P5,"B")+COUNTIF('02_Entrada_Respuestas'!U5:AB5,"B"))-(COUNTIF('02_Entrada_Respuestas'!AS5:AV5,"B")+COUNTIF('02_Entrada_Respuestas'!BA5:BH5,"B")) -> 0 | AC5: =(COUNTIF('02_Entrada_Respuestas'!M5:P5,"C")+COUNTIF('02_Entrada_Respuestas'!U5:AB5,"C"))-(COUNTIF('02_Entrada_Respuestas'!AS5:AV5,"C")+COUNTIF('02_Entrada_Respuestas'!BA5:BH5,"C")) -> 0 | AD5: =(COUNTIF('02_Entrada_Respuestas'!M5:P5,"D")+COUNTIF('02_Entrada_Respuestas'!U5:AB5,"D"))-(COUNTIF('02_Entrada_Respuestas'!AS5:AV5,"D")+COUNTIF('02_Entrada_Respuestas'!BA5:BH5,"D")) -> 0 | AE5: =RIGHT(INDEX(AA$1:AD$1,1,MATCH(MAX(AA5:AD5),AA5:AD5,0)),1) -> D | AF5: =MAX(AA5:AD5) -> 0 | AG5: =IF(MAX(AA5:AD5)>=12*0.5,"Alto",IF(MAX(AA5:AD5)>=12*0.15,"Medio","Mixto/Neutro")) -> Mixto/Neutro | AH5: =(COUNTIF('02_Entrada_Respuestas'!AC5:AJ5,"A"))-(COUNTIF('02_Entrada_Respuestas'!BI5:BP5,"A")) -> 0 | AI5: =(COUNTIF('02_Entrada_Respuestas'!AC5:AJ5,"B"))-(COUNTIF('02_Entrada_Respuestas'!BI5:BP5,"B")) -> 0 | AJ5: =(COUNTIF('02_Entrada_Respuestas'!AC5:AJ5,"C"))-(COUNTIF('02_Entrada_Respuestas'!BI5:BP5,"C")) -> 0 | AK5: =(COUNTIF('02_Entrada_Respuestas'!AC5:AJ5,"D"))-(COUNTIF('02_Entrada_Respuestas'!BI5:BP5,"D")) -> 0 | AL5: =RIGHT(INDEX(AH$1:AK$1,1,MATCH(MAX(AH5:AK5),AH5:AK5,0)),1) -> D | AM5: =MAX(AH5:AK5) -> 0 | AN5: =IF(MAX(AH5:AK5)>=8*0.5,"Alto",IF(MAX(AH5:AK5)>=8*0.15,"Medio","Mixto/Neutro")) -> Mixto/Neutro
A6: ='02_Entrada_Respuestas'!A6 -> 0 | B6: ='02_Entrada_Respuestas'!B6 -> 0 | C6: ='02_Entrada_Respuestas'!C6 -> 0 | D6: =(COUNTIF('02_Entrada_Respuestas'!E6:AJ6,"A"))-(COUNTIF('02_Entrada_Respuestas'!AK6:BP6,"A")) -> 0 | E6: =(COUNTIF('02_Entrada_Respuestas'!E6:AJ6,"B"))-(COUNTIF('02_Entrada_Respuestas'!AK6:BP6,"B")) -> 0 | F6: =(COUNTIF('02_Entrada_Respuestas'!E6:AJ6,"C"))-(COUNTIF('02_Entrada_Respuestas'!AK6:BP6,"C")) -> 0 | G6: =(COUNTIF('02_Entrada_Respuestas'!E6:AJ6,"D"))-(COUNTIF('02_Entrada_Respuestas'!AK6:BP6,"D")) -> 0 | H6: =LEFT(INDEX($D$1:$G$1,1,MATCH(MAX(D6:G6),D6:G6,0)),1) -> D | I6: =MAX(D6:G6) -> 0 | J6: =LEFT(INDEX($D$1:$G$1,1,MATCH(LARGE(D6:G6,2),D6:G6,0)),1) -> D | K6: =LARGE(D6:G6,2) -> 0 | L6: =H6&"/"&J6 -> D/D | M6: =(COUNTIF('02_Entrada_Respuestas'!E6:L6,"A"))-(COUNTIF('02_Entrada_Respuestas'!AK6:AR6,"A")) -> 0 | N6: =(COUNTIF('02_Entrada_Respuestas'!E6:L6,"B"))-(COUNTIF('02_Entrada_Respuestas'!AK6:AR6,"B")) -> 0 | O6: =(COUNTIF('02_Entrada_Respuestas'!E6:L6,"C"))-(COUNTIF('02_Entrada_Respuestas'!AK6:AR6,"C")) -> 0 | P6: =(COUNTIF('02_Entrada_Respuestas'!E6:L6,"D"))-(COUNTIF('02_Entrada_Respuestas'!AK6:AR6,"D")) -> 0 | Q6: =RIGHT(INDEX(M$1:P$1,1,MATCH(MAX(M6:P6),M6:P6,0)),1) -> D | R6: =MAX(M6:P6) -> 0 | S6: =IF(MAX(M6:P6)>=8*0.5,"Alto",IF(MAX(M6:P6)>=8*0.15,"Medio","Mixto/Neutro")) -> Mixto/Neutro | T6: =(COUNTIF('02_Entrada_Respuestas'!Q6:T6,"A"))-(COUNTIF('02_Entrada_Respuestas'!AW6:AZ6,"A")) -> 0 | U6: =(COUNTIF('02_Entrada_Respuestas'!Q6:T6,"B"))-(COUNTIF('02_Entrada_Respuestas'!AW6:AZ6,"B")) -> 0 | V6: =(COUNTIF('02_Entrada_Respuestas'!Q6:T6,"C"))-(COUNTIF('02_Entrada_Respuestas'!AW6:AZ6,"C")) -> 0 | W6: =(COUNTIF('02_Entrada_Respuestas'!Q6:T6,"D"))-(COUNTIF('02_Entrada_Respuestas'!AW6:AZ6,"D")) -> 0 | X6: =RIGHT(INDEX(T$1:W$1,1,MATCH(MAX(T6:W6),T6:W6,0)),1) -> D | Y6: =MAX(T6:W6) -> 0 | Z6: =IF(MAX(T6:W6)>=4*0.5,"Alto",IF(MAX(T6:W6)>=4*0.15,"Medio","Mixto/Neutro")) -> Mixto/Neutro | AA6: =(COUNTIF('02_Entrada_Respuestas'!M6:P6,"A")+COUNTIF('02_Entrada_Respuestas'!U6:AB6,"A"))-(COUNTIF('02_Entrada_Respuestas'!AS6:AV6,"A")+COUNTIF('02_Entrada_Respuestas'!BA6:BH6,"A")) -> 0 | AB6: =(COUNTIF('02_Entrada_Respuestas'!M6:P6,"B")+COUNTIF('02_Entrada_Respuestas'!U6:AB6,"B"))-(COUNTIF('02_Entrada_Respuestas'!AS6:AV6,"B")+COUNTIF('02_Entrada_Respuestas'!BA6:BH6,"B")) -> 0 | AC6: =(COUNTIF('02_Entrada_Respuestas'!M6:P6,"C")+COUNTIF('02_Entrada_Respuestas'!U6:AB6,"C"))-(COUNTIF('02_Entrada_Respuestas'!AS6:AV6,"C")+COUNTIF('02_Entrada_Respuestas'!BA6:BH6,"C")) -> 0 | AD6: =(COUNTIF('02_Entrada_Respuestas'!M6:P6,"D")+COUNTIF('02_Entrada_Respuestas'!U6:AB6,"D"))-(COUNTIF('02_Entrada_Respuestas'!AS6:AV6,"D")+COUNTIF('02_Entrada_Respuestas'!BA6:BH6,"D")) -> 0 | AE6: =RIGHT(INDEX(AA$1:AD$1,1,MATCH(MAX(AA6:AD6),AA6:AD6,0)),1) -> D | AF6: =MAX(AA6:AD6) -> 0 | AG6: =IF(MAX(AA6:AD6)>=12*0.5,"Alto",IF(MAX(AA6:AD6)>=12*0.15,"Medio","Mixto/Neutro")) -> Mixto/Neutro | AH6: =(COUNTIF('02_Entrada_Respuestas'!AC6:AJ6,"A"))-(COUNTIF('02_Entrada_Respuestas'!BI6:BP6,"A")) -> 0 | AI6: =(COUNTIF('02_Entrada_Respuestas'!AC6:AJ6,"B"))-(COUNTIF('02_Entrada_Respuestas'!BI6:BP6,"B")) -> 0 | AJ6: =(COUNTIF('02_Entrada_Respuestas'!AC6:AJ6,"C"))-(COUNTIF('02_Entrada_Respuestas'!BI6:BP6,"C")) -> 0 | AK6: =(COUNTIF('02_Entrada_Respuestas'!AC6:AJ6,"D"))-(COUNTIF('02_Entrada_Respuestas'!BI6:BP6,"D")) -> 0 | AL6: =RIGHT(INDEX(AH$1:AK$1,1,MATCH(MAX(AH6:AK6),AH6:AK6,0)),1) -> D | AM6: =MAX(AH6:AK6) -> 0 | AN6: =IF(MAX(AH6:AK6)>=8*0.5,"Alto",IF(MAX(AH6:AK6)>=8*0.15,"Medio","Mixto/Neutro")) -> Mixto/Neutro
A7: ='02_Entrada_Respuestas'!A7 -> 0 | B7: ='02_Entrada_Respuestas'!B7 -> 0 | C7: ='02_Entrada_Respuestas'!C7 -> 0 | D7: =(COUNTIF('02_Entrada_Respuestas'!E7:AJ7,"A"))-(COUNTIF('02_Entrada_Respuestas'!AK7:BP7,"A")) -> 0 | E7: =(COUNTIF('02_Entrada_Respuestas'!E7:AJ7,"B"))-(COUNTIF('02_Entrada_Respuestas'!AK7:BP7,"B")) -> 0 | F7: =(COUNTIF('02_Entrada_Respuestas'!E7:AJ7,"C"))-(COUNTIF('02_Entrada_Respuestas'!AK7:BP7,"C")) -> 0 | G7: =(COUNTIF('02_Entrada_Respuestas'!E7:AJ7,"D"))-(COUNTIF('02_Entrada_Respuestas'!AK7:BP7,"D")) -> 0 | H7: =LEFT(INDEX($D$1:$G$1,1,MATCH(MAX(D7:G7),D7:G7,0)),1) -> D | I7: =MAX(D7:G7) -> 0 | J7: =LEFT(INDEX($D$1:$G$1,1,MATCH(LARGE(D7:G7,2),D7:G7,0)),1) -> D | K7: =LARGE(D7:G7,2) -> 0 | L7: =H7&"/"&J7 -> D/D | M7: =(COUNTIF('02_Entrada_Respuestas'!E7:L7,"A"))-(COUNTIF('02_Entrada_Respuestas'!AK7:AR7,"A")) -> 0 | N7: =(COUNTIF('02_Entrada_Respuestas'!E7:L7,"B"))-(COUNTIF('02_Entrada_Respuestas'!AK7:AR7,"B")) -> 0 | O7: =(COUNTIF('02_Entrada_Respuestas'!E7:L7,"C"))-(COUNTIF('02_Entrada_Respuestas'!AK7:AR7,"C")) -> 0 | P7: =(COUNTIF('02_Entrada_Respuestas'!E7:L7,"D"))-(COUNTIF('02_Entrada_Respuestas'!AK7:AR7,"D")) -> 0 | Q7: =RIGHT(INDEX(M$1:P$1,1,MATCH(MAX(M7:P7),M7:P7,0)),1) -> D | R7: =MAX(M7:P7) -> 0 | S7: =IF(MAX(M7:P7)>=8*0.5,"Alto",IF(MAX(M7:P7)>=8*0.15,"Medio","Mixto/Neutro")) -> Mixto/Neutro | T7: =(COUNTIF('02_Entrada_Respuestas'!Q7:T7,"A"))-(COUNTIF('02_Entrada_Respuestas'!AW7:AZ7,"A")) -> 0 | U7: =(COUNTIF('02_Entrada_Respuestas'!Q7:T7,"B"))-(COUNTIF('02_Entrada_Respuestas'!AW7:AZ7,"B")) -> 0 | V7: =(COUNTIF('02_Entrada_Respuestas'!Q7:T7,"C"))-(COUNTIF('02_Entrada_Respuestas'!AW7:AZ7,"C")) -> 0 | W7: =(COUNTIF('02_Entrada_Respuestas'!Q7:T7,"D"))-(COUNTIF('02_Entrada_Respuestas'!AW7:AZ7,"D")) -> 0 | X7: =RIGHT(INDEX(T$1:W$1,1,MATCH(MAX(T7:W7),T7:W7,0)),1) -> D | Y7: =MAX(T7:W7) -> 0 | Z7: =IF(MAX(T7:W7)>=4*0.5,"Alto",IF(MAX(T7:W7)>=4*0.15,"Medio","Mixto/Neutro")) -> Mixto/Neutro | AA7: =(COUNTIF('02_Entrada_Respuestas'!M7:P7,"A")+COUNTIF('02_Entrada_Respuestas'!U7:AB7,"A"))-(COUNTIF('02_Entrada_Respuestas'!AS7:AV7,"A")+COUNTIF('02_Entrada_Respuestas'!BA7:BH7,"A")) -> 0 | AB7: =(COUNTIF('02_Entrada_Respuestas'!M7:P7,"B")+COUNTIF('02_Entrada_Respuestas'!U7:AB7,"B"))-(COUNTIF('02_Entrada_Respuestas'!AS7:AV7,"B")+COUNTIF('02_Entrada_Respuestas'!BA7:BH7,"B")) -> 0 | AC7: =(COUNTIF('02_Entrada_Respuestas'!M7:P7,"C")+COUNTIF('02_Entrada_Respuestas'!U7:AB7,"C"))-(COUNTIF('02_Entrada_Respuestas'!AS7:AV7,"C")+COUNTIF('02_Entrada_Respuestas'!BA7:BH7,"C")) -> 0 | AD7: =(COUNTIF('02_Entrada_Respuestas'!M7:P7,"D")+COUNTIF('02_Entrada_Respuestas'!U7:AB7,"D"))-(COUNTIF('02_Entrada_Respuestas'!AS7:AV7,"D")+COUNTIF('02_Entrada_Respuestas'!BA7:BH7,"D")) -> 0 | AE7: =RIGHT(INDEX(AA$1:AD$1,1,MATCH(MAX(AA7:AD7),AA7:AD7,0)),1) -> D | AF7: =MAX(AA7:AD7) -> 0 | AG7: =IF(MAX(AA7:AD7)>=12*0.5,"Alto",IF(MAX(AA7:AD7)>=12*0.15,"Medio","Mixto/Neutro")) -> Mixto/Neutro | AH7: =(COUNTIF('02_Entrada_Respuestas'!AC7:AJ7,"A"))-(COUNTIF('02_Entrada_Respuestas'!BI7:BP7,"A")) -> 0 | AI7: =(COUNTIF('02_Entrada_Respuestas'!AC7:AJ7,"B"))-(COUNTIF('02_Entrada_Respuestas'!BI7:BP7,"B")) -> 0 | AJ7: =(COUNTIF('02_Entrada_Respuestas'!AC7:AJ7,"C"))-(COUNTIF('02_Entrada_Respuestas'!BI7:BP7,"C")) -> 0 | AK7: =(COUNTIF('02_Entrada_Respuestas'!AC7:AJ7,"D"))-(COUNTIF('02_Entrada_Respuestas'!BI7:BP7,"D")) -> 0 | AL7: =RIGHT(INDEX(AH$1:AK$1,1,MATCH(MAX(AH7:AK7),AH7:AK7,0)),1) -> D | AM7: =MAX(AH7:AK7) -> 0 | AN7: =IF(MAX(AH7:AK7)>=8*0.5,"Alto",IF(MAX(AH7:AK7)>=8*0.15,"Medio","Mixto/Neutro")) -> Mixto/Neutro
A8: ='02_Entrada_Respuestas'!A8 -> 0 | B8: ='02_Entrada_Respuestas'!B8 -> 0 | C8: ='02_Entrada_Respuestas'!C8 -> 0 | D8: =(COUNTIF('02_Entrada_Respuestas'!E8:AJ8,"A"))-(COUNTIF('02_Entrada_Respuestas'!AK8:BP8,"A")) -> 0 | E8: =(COUNTIF('02_Entrada_Respuestas'!E8:AJ8,"B"))-(COUNTIF('02_Entrada_Respuestas'!AK8:BP8,"B")) -> 0 | F8: =(COUNTIF('02_Entrada_Respuestas'!E8:AJ8,"C"))-(COUNTIF('02_Entrada_Respuestas'!AK8:BP8,"C")) -> 0 | G8: =(COUNTIF('02_Entrada_Respuestas'!E8:AJ8,"D"))-(COUNTIF('02_Entrada_Respuestas'!AK8:BP8,"D")) -> 0 | H8: =LEFT(INDEX($D$1:$G$1,1,MATCH(MAX(D8:G8),D8:G8,0)),1) -> D | I8: =MAX(D8:G8) -> 0 | J8: =LEFT(INDEX($D$1:$G$1,1,MATCH(LARGE(D8:G8,2),D8:G8,0)),1) -> D | K8: =LARGE(D8:G8,2) -> 0 | L8: =H8&"/"&J8 -> D/D | M8: =(COUNTIF('02_Entrada_Respuestas'!E8:L8,"A"))-(COUNTIF('02_Entrada_Respuestas'!AK8:AR8,"A")) -> 0 | N8: =(COUNTIF('02_Entrada_Respuestas'!E8:L8,"B"))-(COUNTIF('02_Entrada_Respuestas'!AK8:AR8,"B")) -> 0 | O8: =(COUNTIF('02_Entrada_Respuestas'!E8:L8,"C"))-(COUNTIF('02_Entrada_Respuestas'!AK8:AR8,"C")) -> 0 | P8: =(COUNTIF('02_Entrada_Respuestas'!E8:L8,"D"))-(COUNTIF('02_Entrada_Respuestas'!AK8:AR8,"D")) -> 0 | Q8: =RIGHT(INDEX(M$1:P$1,1,MATCH(MAX(M8:P8),M8:P8,0)),1) -> D | R8: =MAX(M8:P8) -> 0 | S8: =IF(MAX(M8:P8)>=8*0.5,"Alto",IF(MAX(M8:P8)>=8*0.15,"Medio","Mixto/Neutro")) -> Mixto/Neutro | T8: =(COUNTIF('02_Entrada_Respuestas'!Q8:T8,"A"))-(COUNTIF('02_Entrada_Respuestas'!AW8:AZ8,"A")) -> 0 | U8: =(COUNTIF('02_Entrada_Respuestas'!Q8:T8,"B"))-(COUNTIF('02_Entrada_Respuestas'!AW8:AZ8,"B")) -> 0 | V8: =(COUNTIF('02_Entrada_Respuestas'!Q8:T8,"C"))-(COUNTIF('02_Entrada_Respuestas'!AW8:AZ8,"C")) -> 0 | W8: =(COUNTIF('02_Entrada_Respuestas'!Q8:T8,"D"))-(COUNTIF('02_Entrada_Respuestas'!AW8:AZ8,"D")) -> 0 | X8: =RIGHT(INDEX(T$1:W$1,1,MATCH(MAX(T8:W8),T8:W8,0)),1) -> D | Y8: =MAX(T8:W8) -> 0 | Z8: =IF(MAX(T8:W8)>=4*0.5,"Alto",IF(MAX(T8:W8)>=4*0.15,"Medio","Mixto/Neutro")) -> Mixto/Neutro | AA8: =(COUNTIF('02_Entrada_Respuestas'!M8:P8,"A")+COUNTIF('02_Entrada_Respuestas'!U8:AB8,"A"))-(COUNTIF('02_Entrada_Respuestas'!AS8:AV8,"A")+COUNTIF('02_Entrada_Respuestas'!BA8:BH8,"A")) -> 0 | AB8: =(COUNTIF('02_Entrada_Respuestas'!M8:P8,"B")+COUNTIF('02_Entrada_Respuestas'!U8:AB8,"B"))-(COUNTIF('02_Entrada_Respuestas'!AS8:AV8,"B")+COUNTIF('02_Entrada_Respuestas'!BA8:BH8,"B")) -> 0 | AC8: =(COUNTIF('02_Entrada_Respuestas'!M8:P8,"C")+COUNTIF('02_Entrada_Respuestas'!U8:AB8,"C"))-(COUNTIF('02_Entrada_Respuestas'!AS8:AV8,"C")+COUNTIF('02_Entrada_Respuestas'!BA8:BH8,"C")) -> 0 | AD8: =(COUNTIF('02_Entrada_Respuestas'!M8:P8,"D")+COUNTIF('02_Entrada_Respuestas'!U8:AB8,"D"))-(COUNTIF('02_Entrada_Respuestas'!AS8:AV8,"D")+COUNTIF('02_Entrada_Respuestas'!BA8:BH8,"D")) -> 0 | AE8: =RIGHT(INDEX(AA$1:AD$1,1,MATCH(MAX(AA8:AD8),AA8:AD8,0)),1) -> D | AF8: =MAX(AA8:AD8) -> 0 | AG8: =IF(MAX(AA8:AD8)>=12*0.5,"Alto",IF(MAX(AA8:AD8)>=12*0.15,"Medio","Mixto/Neutro")) -> Mixto/Neutro | AH8: =(COUNTIF('02_Entrada_Respuestas'!AC8:AJ8,"A"))-(COUNTIF('02_Entrada_Respuestas'!BI8:BP8,"A")) -> 0 | AI8: =(COUNTIF('02_Entrada_Respuestas'!AC8:AJ8,"B"))-(COUNTIF('02_Entrada_Respuestas'!BI8:BP8,"B")) -> 0 | AJ8: =(COUNTIF('02_Entrada_Respuestas'!AC8:AJ8,"C"))-(COUNTIF('02_Entrada_Respuestas'!BI8:BP8,"C")) -> 0 | AK8: =(COUNTIF('02_Entrada_Respuestas'!AC8:AJ8,"D"))-(COUNTIF('02_Entrada_Respuestas'!BI8:BP8,"D")) -> 0 | AL8: =RIGHT(INDEX(AH$1:AK$1,1,MATCH(MAX(AH8:AK8),AH8:AK8,0)),1) -> D | AM8: =MAX(AH8:AK8) -> 0 | AN8: =IF(MAX(AH8:AK8)>=8*0.5,"Alto",IF(MAX(AH8:AK8)>=8*0.15,"Medio","Mixto/Neutro")) -> Mixto/Neutro
A9: ='02_Entrada_Respuestas'!A9 -> 0 | B9: ='02_Entrada_Respuestas'!B9 -> 0 | C9: ='02_Entrada_Respuestas'!C9 -> 0 | D9: =(COUNTIF('02_Entrada_Respuestas'!E9:AJ9,"A"))-(COUNTIF('02_Entrada_Respuestas'!AK9:BP9,"A")) -> 0 | E9: =(COUNTIF('02_Entrada_Respuestas'!E9:AJ9,"B"))-(COUNTIF('02_Entrada_Respuestas'!AK9:BP9,"B")) -> 0 | F9: =(COUNTIF('02_Entrada_Respuestas'!E9:AJ9,"C"))-(COUNTIF('02_Entrada_Respuestas'!AK9:BP9,"C")) -> 0 | G9: =(COUNTIF('02_Entrada_Respuestas'!E9:AJ9,"D"))-(COUNTIF('02_Entrada_Respuestas'!AK9:BP9,"D")) -> 0 | H9: =LEFT(INDEX($D$1:$G$1,1,MATCH(MAX(D9:G9),D9:G9,0)),1) -> D | I9: =MAX(D9:G9) -> 0 | J9: =LEFT(INDEX($D$1:$G$1,1,MATCH(LARGE(D9:G9,2),D9:G9,0)),1) -> D | K9: =LARGE(D9:G9,2) -> 0 | L9: =H9&"/"&J9 -> D/D | M9: =(COUNTIF('02_Entrada_Respuestas'!E9:L9,"A"))-(COUNTIF('02_Entrada_Respuestas'!AK9:AR9,"A")) -> 0 | N9: =(COUNTIF('02_Entrada_Respuestas'!E9:L9,"B"))-(COUNTIF('02_Entrada_Respuestas'!AK9:AR9,"B")) -> 0 | O9: =(COUNTIF('02_Entrada_Respuestas'!E9:L9,"C"))-(COUNTIF('02_Entrada_Respuestas'!AK9:AR9,"C")) -> 0 | P9: =(COUNTIF('02_Entrada_Respuestas'!E9:L9,"D"))-(COUNTIF('02_Entrada_Respuestas'!AK9:AR9,"D")) -> 0 | Q9: =RIGHT(INDEX(M$1:P$1,1,MATCH(MAX(M9:P9),M9:P9,0)),1) -> D | R9: =MAX(M9:P9) -> 0 | S9: =IF(MAX(M9:P9)>=8*0.5,"Alto",IF(MAX(M9:P9)>=8*0.15,"Medio","Mixto/Neutro")) -> Mixto/Neutro | T9: =(COUNTIF('02_Entrada_Respuestas'!Q9:T9,"A"))-(COUNTIF('02_Entrada_Respuestas'!AW9:AZ9,"A")) -> 0 | U9: =(COUNTIF('02_Entrada_Respuestas'!Q9:T9,"B"))-(COUNTIF('02_Entrada_Respuestas'!AW9:AZ9,"B")) -> 0 | V9: =(COUNTIF('02_Entrada_Respuestas'!Q9:T9,"C"))-(COUNTIF('02_Entrada_Respuestas'!AW9:AZ9,"C")) -> 0 | W9: =(COUNTIF('02_Entrada_Respuestas'!Q9:T9,"D"))-(COUNTIF('02_Entrada_Respuestas'!AW9:AZ9,"D")) -> 0 | X9: =RIGHT(INDEX(T$1:W$1,1,MATCH(MAX(T9:W9),T9:W9,0)),1) -> D | Y9: =MAX(T9:W9) -> 0 | Z9: =IF(MAX(T9:W9)>=4*0.5,"Alto",IF(MAX(T9:W9)>=4*0.15,"Medio","Mixto/Neutro")) -> Mixto/Neutro | AA9: =(COUNTIF('02_Entrada_Respuestas'!M9:P9,"A")+COUNTIF('02_Entrada_Respuestas'!U9:AB9,"A"))-(COUNTIF('02_Entrada_Respuestas'!AS9:AV9,"A")+COUNTIF('02_Entrada_Respuestas'!BA9:BH9,"A")) -> 0 | AB9: =(COUNTIF('02_Entrada_Respuestas'!M9:P9,"B")+COUNTIF('02_Entrada_Respuestas'!U9:AB9,"B"))-(COUNTIF('02_Entrada_Respuestas'!AS9:AV9,"B")+COUNTIF('02_Entrada_Respuestas'!BA9:BH9,"B")) -> 0 | AC9: =(COUNTIF('02_Entrada_Respuestas'!M9:P9,"C")+COUNTIF('02_Entrada_Respuestas'!U9:AB9,"C"))-(COUNTIF('02_Entrada_Respuestas'!AS9:AV9,"C")+COUNTIF('02_Entrada_Respuestas'!BA9:BH9,"C")) -> 0 | AD9: =(COUNTIF('02_Entrada_Respuestas'!M9:P9,"D")+COUNTIF('02_Entrada_Respuestas'!U9:AB9,"D"))-(COUNTIF('02_Entrada_Respuestas'!AS9:AV9,"D")+COUNTIF('02_Entrada_Respuestas'!BA9:BH9,"D")) -> 0 | AE9: =RIGHT(INDEX(AA$1:AD$1,1,MATCH(MAX(AA9:AD9),AA9:AD9,0)),1) -> D | AF9: =MAX(AA9:AD9) -> 0 | AG9: =IF(MAX(AA9:AD9)>=12*0.5,"Alto",IF(MAX(AA9:AD9)>=12*0.15,"Medio","Mixto/Neutro")) -> Mixto/Neutro | AH9: =(COUNTIF('02_Entrada_Respuestas'!AC9:AJ9,"A"))-(COUNTIF('02_Entrada_Respuestas'!BI9:BP9,"A")) -> 0 | AI9: =(COUNTIF('02_Entrada_Respuestas'!AC9:AJ9,"B"))-(COUNTIF('02_Entrada_Respuestas'!BI9:BP9,"B")) -> 0 | AJ9: =(COUNTIF('02_Entrada_Respuestas'!AC9:AJ9,"C"))-(COUNTIF('02_Entrada_Respuestas'!BI9:BP9,"C")) -> 0 | AK9: =(COUNTIF('02_Entrada_Respuestas'!AC9:AJ9,"D"))-(COUNTIF('02_Entrada_Respuestas'!BI9:BP9,"D")) -> 0 | AL9: =RIGHT(INDEX(AH$1:AK$1,1,MATCH(MAX(AH9:AK9),AH9:AK9,0)),1) -> D | AM9: =MAX(AH9:AK9) -> 0 | AN9: =IF(MAX(AH9:AK9)>=8*0.5,"Alto",IF(MAX(AH9:AK9)>=8*0.15,"Medio","Mixto/Neutro")) -> Mixto/Neutro
A10: ='02_Entrada_Respuestas'!A10 -> 0 | B10: ='02_Entrada_Respuestas'!B10 -> 0 | C10: ='02_Entrada_Respuestas'!C10 -> 0 | D10: =(COUNTIF('02_Entrada_Respuestas'!E10:AJ10,"A"))-(COUNTIF('02_Entrada_Respuestas'!AK10:BP10,"A")) -> 0 | E10: =(COUNTIF('02_Entrada_Respuestas'!E10:AJ10,"B"))-(COUNTIF('02_Entrada_Respuestas'!AK10:BP10,"B")) -> 0 | F10: =(COUNTIF('02_Entrada_Respuestas'!E10:AJ10,"C"))-(COUNTIF('02_Entrada_Respuestas'!AK10:BP10,"C")) -> 0 | G10: =(COUNTIF('02_Entrada_Respuestas'!E10:AJ10,"D"))-(COUNTIF('02_Entrada_Respuestas'!AK10:BP10,"D")) -> 0 | H10: =LEFT(INDEX($D$1:$G$1,1,MATCH(MAX(D10:G10),D10:G10,0)),1) -> D | I10: =MAX(D10:G10) -> 0 | J10: =LEFT(INDEX($D$1:$G$1,1,MATCH(LARGE(D10:G10,2),D10:G10,0)),1) -> D | K10: =LARGE(D10:G10,2) -> 0 | L10: =H10&"/"&J10 -> D/D | M10: =(COUNTIF('02_Entrada_Respuestas'!E10:L10,"A"))-(COUNTIF('02_Entrada_Respuestas'!AK10:AR10,"A")) -> 0 | N10: =(COUNTIF('02_Entrada_Respuestas'!E10:L10,"B"))-(COUNTIF('02_Entrada_Respuestas'!AK10:AR10,"B")) -> 0 | O10: =(COUNTIF('02_Entrada_Respuestas'!E10:L10,"C"))-(COUNTIF('02_Entrada_Respuestas'!AK10:AR10,"C")) -> 0 | P10: =(COUNTIF('02_Entrada_Respuestas'!E10:L10,"D"))-(COUNTIF('02_Entrada_Respuestas'!AK10:AR10,"D")) -> 0 | Q10: =RIGHT(INDEX(M$1:P$1,1,MATCH(MAX(M10:P10),M10:P10,0)),1) -> D | R10: =MAX(M10:P10) -> 0 | S10: =IF(MAX(M10:P10)>=8*0.5,"Alto",IF(MAX(M10:P10)>=8*0.15,"Medio","Mixto/Neutro")) -> Mixto/Neutro | T10: =(COUNTIF('02_Entrada_Respuestas'!Q10:T10,"A"))-(COUNTIF('02_Entrada_Respuestas'!AW10:AZ10,"A")) -> 0 | U10: =(COUNTIF('02_Entrada_Respuestas'!Q10:T10,"B"))-(COUNTIF('02_Entrada_Respuestas'!AW10:AZ10,"B")) -> 0 | V10: =(COUNTIF('02_Entrada_Respuestas'!Q10:T10,"C"))-(COUNTIF('02_Entrada_Respuestas'!AW10:AZ10,"C")) -> 0 | W10: =(COUNTIF('02_Entrada_Respuestas'!Q10:T10,"D"))-(COUNTIF('02_Entrada_Respuestas'!AW10:AZ10,"D")) -> 0 | X10: =RIGHT(INDEX(T$1:W$1,1,MATCH(MAX(T10:W10),T10:W10,0)),1) -> D | Y10: =MAX(T10:W10) -> 0 | Z10: =IF(MAX(T10:W10)>=4*0.5,"Alto",IF(MAX(T10:W10)>=4*0.15,"Medio","Mixto/Neutro")) -> Mixto/Neutro | AA10: =(COUNTIF('02_Entrada_Respuestas'!M10:P10,"A")+COUNTIF('02_Entrada_Respuestas'!U10:AB10,"A"))-(COUNTIF('02_Entrada_Respuestas'!AS10:AV10,"A")+COUNTIF('02_Entrada_Respuestas'!BA10:BH10,"A")) -> 0 | AB10: =(COUNTIF('02_Entrada_Respuestas'!M10:P10,"B")+COUNTIF('02_Entrada_Respuestas'!U10:AB10,"B"))-(COUNTIF('02_Entrada_Respuestas'!AS10:AV10,"B")+COUNTIF('02_Entrada_Respuestas'!BA10:BH10,"B")) -> 0 | AC10: =(COUNTIF('02_Entrada_Respuestas'!M10:P10,"C")+COUNTIF('02_Entrada_Respuestas'!U10:AB10,"C"))-(COUNTIF('02_Entrada_Respuestas'!AS10:AV10,"C")+COUNTIF('02_Entrada_Respuestas'!BA10:BH10,"C")) -> 0 | AD10: =(COUNTIF('02_Entrada_Respuestas'!M10:P10,"D")+COUNTIF('02_Entrada_Respuestas'!U10:AB10,"D"))-(COUNTIF('02_Entrada_Respuestas'!AS10:AV10,"D")+COUNTIF('02_Entrada_Respuestas'!BA10:BH10,"D")) -> 0 | AE10: =RIGHT(INDEX(AA$1:AD$1,1,MATCH(MAX(AA10:AD10),AA10:AD10,0)),1) -> D | AF10: =MAX(AA10:AD10) -> 0 | AG10: =IF(MAX(AA10:AD10)>=12*0.5,"Alto",IF(MAX(AA10:AD10)>=12*0.15,"Medio","Mixto/Neutro")) -> Mixto/Neutro | AH10: =(COUNTIF('02_Entrada_Respuestas'!AC10:AJ10,"A"))-(COUNTIF('02_Entrada_Respuestas'!BI10:BP10,"A")) -> 0 | AI10: =(COUNTIF('02_Entrada_Respuestas'!AC10:AJ10,"B"))-(COUNTIF('02_Entrada_Respuestas'!BI10:BP10,"B")) -> 0 | AJ10: =(COUNTIF('02_Entrada_Respuestas'!AC10:AJ10,"C"))-(COUNTIF('02_Entrada_Respuestas'!BI10:BP10,"C")) -> 0 | AK10: =(COUNTIF('02_Entrada_Respuestas'!AC10:AJ10,"D"))-(COUNTIF('02_Entrada_Respuestas'!BI10:BP10,"D")) -> 0 | AL10: =RIGHT(INDEX(AH$1:AK$1,1,MATCH(MAX(AH10:AK10),AH10:AK10,0)),1) -> D | AM10: =MAX(AH10:AK10) -> 0 | AN10: =IF(MAX(AH10:AK10)>=8*0.5,"Alto",IF(MAX(AH10:AK10)>=8*0.15,"Medio","Mixto/Neutro")) -> Mixto/Neutro
A11: ='02_Entrada_Respuestas'!A11 -> 0 | B11: ='02_Entrada_Respuestas'!B11 -> 0 | C11: ='02_Entrada_Respuestas'!C11 -> 0 | D11: =(COUNTIF('02_Entrada_Respuestas'!E11:AJ11,"A"))-(COUNTIF('02_Entrada_Respuestas'!AK11:BP11,"A")) -> 0 | E11: =(COUNTIF('02_Entrada_Respuestas'!E11:AJ11,"B"))-(COUNTIF('02_Entrada_Respuestas'!AK11:BP11,"B")) -> 0 | F11: =(COUNTIF('02_Entrada_Respuestas'!E11:AJ11,"C"))-(COUNTIF('02_Entrada_Respuestas'!AK11:BP11,"C")) -> 0 | G11: =(COUNTIF('02_Entrada_Respuestas'!E11:AJ11,"D"))-(COUNTIF('02_Entrada_Respuestas'!AK11:BP11,"D")) -> 0 | H11: =LEFT(INDEX($D$1:$G$1,1,MATCH(MAX(D11:G11),D11:G11,0)),1) -> D | I11: =MAX(D11:G11) -> 0 | J11: =LEFT(INDEX($D$1:$G$1,1,MATCH(LARGE(D11:G11,2),D11:G11,0)),1) -> D | K11: =LARGE(D11:G11,2) -> 0 | L11: =H11&"/"&J11 -> D/D | M11: =(COUNTIF('02_Entrada_Respuestas'!E11:L11,"A"))-(COUNTIF('02_Entrada_Respuestas'!AK11:AR11,"A")) -> 0 | N11: =(COUNTIF('02_Entrada_Respuestas'!E11:L11,"B"))-(COUNTIF('02_Entrada_Respuestas'!AK11:AR11,"B")) -> 0 | O11: =(COUNTIF('02_Entrada_Respuestas'!E11:L11,"C"))-(COUNTIF('02_Entrada_Respuestas'!AK11:AR11,"C")) -> 0 | P11: =(COUNTIF('02_Entrada_Respuestas'!E11:L11,"D"))-(COUNTIF('02_Entrada_Respuestas'!AK11:AR11,"D")) -> 0 | Q11: =RIGHT(INDEX(M$1:P$1,1,MATCH(MAX(M11:P11),M11:P11,0)),1) -> D | R11: =MAX(M11:P11) -> 0 | S11: =IF(MAX(M11:P11)>=8*0.5,"Alto",IF(MAX(M11:P11)>=8*0.15,"Medio","Mixto/Neutro")) -> Mixto/Neutro | T11: =(COUNTIF('02_Entrada_Respuestas'!Q11:T11,"A"))-(COUNTIF('02_Entrada_Respuestas'!AW11:AZ11,"A")) -> 0 | U11: =(COUNTIF('02_Entrada_Respuestas'!Q11:T11,"B"))-(COUNTIF('02_Entrada_Respuestas'!AW11:AZ11,"B")) -> 0 | V11: =(COUNTIF('02_Entrada_Respuestas'!Q11:T11,"C"))-(COUNTIF('02_Entrada_Respuestas'!AW11:AZ11,"C")) -> 0 | W11: =(COUNTIF('02_Entrada_Respuestas'!Q11:T11,"D"))-(COUNTIF('02_Entrada_Respuestas'!AW11:AZ11,"D")) -> 0 | X11: =RIGHT(INDEX(T$1:W$1,1,MATCH(MAX(T11:W11),T11:W11,0)),1) -> D | Y11: =MAX(T11:W11) -> 0 | Z11: =IF(MAX(T11:W11)>=4*0.5,"Alto",IF(MAX(T11:W11)>=4*0.15,"Medio","Mixto/Neutro")) -> Mixto/Neutro | AA11: =(COUNTIF('02_Entrada_Respuestas'!M11:P11,"A")+COUNTIF('02_Entrada_Respuestas'!U11:AB11,"A"))-(COUNTIF('02_Entrada_Respuestas'!AS11:AV11,"A")+COUNTIF('02_Entrada_Respuestas'!BA11:BH11,"A")) -> 0 | AB11: =(COUNTIF('02_Entrada_Respuestas'!M11:P11,"B")+COUNTIF('02_Entrada_Respuestas'!U11:AB11,"B"))-(COUNTIF('02_Entrada_Respuestas'!AS11:AV11,"B")+COUNTIF('02_Entrada_Respuestas'!BA11:BH11,"B")) -> 0 | AC11: =(COUNTIF('02_Entrada_Respuestas'!M11:P11,"C")+COUNTIF('02_Entrada_Respuestas'!U11:AB11,"C"))-(COUNTIF('02_Entrada_Respuestas'!AS11:AV11,"C")+COUNTIF('02_Entrada_Respuestas'!BA11:BH11,"C")) -> 0 | AD11: =(COUNTIF('02_Entrada_Respuestas'!M11:P11,"D")+COUNTIF('02_Entrada_Respuestas'!U11:AB11,"D"))-(COUNTIF('02_Entrada_Respuestas'!AS11:AV11,"D")+COUNTIF('02_Entrada_Respuestas'!BA11:BH11,"D")) -> 0 | AE11: =RIGHT(INDEX(AA$1:AD$1,1,MATCH(MAX(AA11:AD11),AA11:AD11,0)),1) -> D | AF11: =MAX(AA11:AD11) -> 0 | AG11: =IF(MAX(AA11:AD11)>=12*0.5,"Alto",IF(MAX(AA11:AD11)>=12*0.15,"Medio","Mixto/Neutro")) -> Mixto/Neutro | AH11: =(COUNTIF('02_Entrada_Respuestas'!AC11:AJ11,"A"))-(COUNTIF('02_Entrada_Respuestas'!BI11:BP11,"A")) -> 0 | AI11: =(COUNTIF('02_Entrada_Respuestas'!AC11:AJ11,"B"))-(COUNTIF('02_Entrada_Respuestas'!BI11:BP11,"B")) -> 0 | AJ11: =(COUNTIF('02_Entrada_Respuestas'!AC11:AJ11,"C"))-(COUNTIF('02_Entrada_Respuestas'!BI11:BP11,"C")) -> 0 | AK11: =(COUNTIF('02_Entrada_Respuestas'!AC11:AJ11,"D"))-(COUNTIF('02_Entrada_Respuestas'!BI11:BP11,"D")) -> 0 | AL11: =RIGHT(INDEX(AH$1:AK$1,1,MATCH(MAX(AH11:AK11),AH11:AK11,0)),1) -> D | AM11: =MAX(AH11:AK11) -> 0 | AN11: =IF(MAX(AH11:AK11)>=8*0.5,"Alto",IF(MAX(AH11:AK11)>=8*0.15,"Medio","Mixto/Neutro")) -> Mixto/Neutro
A12: ='02_Entrada_Respuestas'!A12 -> 0 | B12: ='02_Entrada_Respuestas'!B12 -> 0 | C12: ='02_Entrada_Respuestas'!C12 -> 0 | D12: =(COUNTIF('02_Entrada_Respuestas'!E12:AJ12,"A"))-(COUNTIF('02_Entrada_Respuestas'!AK12:BP12,"A")) -> 0 | E12: =(COUNTIF('02_Entrada_Respuestas'!E12:AJ12,"B"))-(COUNTIF('02_Entrada_Respuestas'!AK12:BP12,"B")) -> 0 | F12: =(COUNTIF('02_Entrada_Respuestas'!E12:AJ12,"C"))-(COUNTIF('02_Entrada_Respuestas'!AK12:BP12,"C")) -> 0 | G12: =(COUNTIF('02_Entrada_Respuestas'!E12:AJ12,"D"))-(COUNTIF('02_Entrada_Respuestas'!AK12:BP12,"D")) -> 0 | H12: =LEFT(INDEX($D$1:$G$1,1,MATCH(MAX(D12:G12),D12:G12,0)),1) -> D | I12: =MAX(D12:G12) -> 0 | J12: =LEFT(INDEX($D$1:$G$1,1,MATCH(LARGE(D12:G12,2),D12:G12,0)),1) -> D | K12: =LARGE(D12:G12,2) -> 0 | L12: =H12&"/"&J12 -> D/D | M12: =(COUNTIF('02_Entrada_Respuestas'!E12:L12,"A"))-(COUNTIF('02_Entrada_Respuestas'!AK12:AR12,"A")) -> 0 | N12: =(COUNTIF('02_Entrada_Respuestas'!E12:L12,"B"))-(COUNTIF('02_Entrada_Respuestas'!AK12:AR12,"B")) -> 0 | O12: =(COUNTIF('02_Entrada_Respuestas'!E12:L12,"C"))-(COUNTIF('02_Entrada_Respuestas'!AK12:AR12,"C")) -> 0 | P12: =(COUNTIF('02_Entrada_Respuestas'!E12:L12,"D"))-(COUNTIF('02_Entrada_Respuestas'!AK12:AR12,"D")) -> 0 | Q12: =RIGHT(INDEX(M$1:P$1,1,MATCH(MAX(M12:P12),M12:P12,0)),1) -> D | R12: =MAX(M12:P12) -> 0 | S12: =IF(MAX(M12:P12)>=8*0.5,"Alto",IF(MAX(M12:P12)>=8*0.15,"Medio","Mixto/Neutro")) -> Mixto/Neutro | T12: =(COUNTIF('02_Entrada_Respuestas'!Q12:T12,"A"))-(COUNTIF('02_Entrada_Respuestas'!AW12:AZ12,"A")) -> 0 | U12: =(COUNTIF('02_Entrada_Respuestas'!Q12:T12,"B"))-(COUNTIF('02_Entrada_Respuestas'!AW12:AZ12,"B")) -> 0 | V12: =(COUNTIF('02_Entrada_Respuestas'!Q12:T12,"C"))-(COUNTIF('02_Entrada_Respuestas'!AW12:AZ12,"C")) -> 0 | W12: =(COUNTIF('02_Entrada_Respuestas'!Q12:T12,"D"))-(COUNTIF('02_Entrada_Respuestas'!AW12:AZ12,"D")) -> 0 | X12: =RIGHT(INDEX(T$1:W$1,1,MATCH(MAX(T12:W12),T12:W12,0)),1) -> D | Y12: =MAX(T12:W12) -> 0 | Z12: =IF(MAX(T12:W12)>=4*0.5,"Alto",IF(MAX(T12:W12)>=4*0.15,"Medio","Mixto/Neutro")) -> Mixto/Neutro | AA12: =(COUNTIF('02_Entrada_Respuestas'!M12:P12,"A")+COUNTIF('02_Entrada_Respuestas'!U12:AB12,"A"))-(COUNTIF('02_Entrada_Respuestas'!AS12:AV12,"A")+COUNTIF('02_Entrada_Respuestas'!BA12:BH12,"A")) -> 0 | AB12: =(COUNTIF('02_Entrada_Respuestas'!M12:P12,"B")+COUNTIF('02_Entrada_Respuestas'!U12:AB12,"B"))-(COUNTIF('02_Entrada_Respuestas'!AS12:AV12,"B")+COUNTIF('02_Entrada_Respuestas'!BA12:BH12,"B")) -> 0 | AC12: =(COUNTIF('02_Entrada_Respuestas'!M12:P12,"C")+COUNTIF('02_Entrada_Respuestas'!U12:AB12,"C"))-(COUNTIF('02_Entrada_Respuestas'!AS12:AV12,"C")+COUNTIF('02_Entrada_Respuestas'!BA12:BH12,"C")) -> 0 | AD12: =(COUNTIF('02_Entrada_Respuestas'!M12:P12,"D")+COUNTIF('02_Entrada_Respuestas'!U12:AB12,"D"))-(COUNTIF('02_Entrada_Respuestas'!AS12:AV12,"D")+COUNTIF('02_Entrada_Respuestas'!BA12:BH12,"D")) -> 0 | AE12: =RIGHT(INDEX(AA$1:AD$1,1,MATCH(MAX(AA12:AD12),AA12:AD12,0)),1) -> D | AF12: =MAX(AA12:AD12) -> 0 | AG12: =IF(MAX(AA12:AD12)>=12*0.5,"Alto",IF(MAX(AA12:AD12)>=12*0.15,"Medio","Mixto/Neutro")) -> Mixto/Neutro | AH12: =(COUNTIF('02_Entrada_Respuestas'!AC12:AJ12,"A"))-(COUNTIF('02_Entrada_Respuestas'!BI12:BP12,"A")) -> 0 | AI12: =(COUNTIF('02_Entrada_Respuestas'!AC12:AJ12,"B"))-(COUNTIF('02_Entrada_Respuestas'!BI12:BP12,"B")) -> 0 | AJ12: =(COUNTIF('02_Entrada_Respuestas'!AC12:AJ12,"C"))-(COUNTIF('02_Entrada_Respuestas'!BI12:BP12,"C")) -> 0 | AK12: =(COUNTIF('02_Entrada_Respuestas'!AC12:AJ12,"D"))-(COUNTIF('02_Entrada_Respuestas'!BI12:BP12,"D")) -> 0 | AL12: =RIGHT(INDEX(AH$1:AK$1,1,MATCH(MAX(AH12:AK12),AH12:AK12,0)),1) -> D | AM12: =MAX(AH12:AK12) -> 0 | AN12: =IF(MAX(AH12:AK12)>=8*0.5,"Alto",IF(MAX(AH12:AK12)>=8*0.15,"Medio","Mixto/Neutro")) -> Mixto/Neutro
A13: ='02_Entrada_Respuestas'!A13 -> 0 | B13: ='02_Entrada_Respuestas'!B13 -> 0 | C13: ='02_Entrada_Respuestas'!C13 -> 0 | D13: =(COUNTIF('02_Entrada_Respuestas'!E13:AJ13,"A"))-(COUNTIF('02_Entrada_Respuestas'!AK13:BP13,"A")) -> 0 | E13: =(COUNTIF('02_Entrada_Respuestas'!E13:AJ13,"B"))-(COUNTIF('02_Entrada_Respuestas'!AK13:BP13,"B")) -> 0 | F13: =(COUNTIF('02_Entrada_Respuestas'!E13:AJ13,"C"))-(COUNTIF('02_Entrada_Respuestas'!AK13:BP13,"C")) -> 0 | G13: =(COUNTIF('02_Entrada_Respuestas'!E13:AJ13,"D"))-(COUNTIF('02_Entrada_Respuestas'!AK13:BP13,"D")) -> 0 | H13: =LEFT(INDEX($D$1:$G$1,1,MATCH(MAX(D13:G13),D13:G13,0)),1) -> D | I13: =MAX(D13:G13) -> 0 | J13: =LEFT(INDEX($D$1:$G$1,1,MATCH(LARGE(D13:G13,2),D13:G13,0)),1) -> D | K13: =LARGE(D13:G13,2) -> 0 | L13: =H13&"/"&J13 -> D/D | M13: =(COUNTIF('02_Entrada_Respuestas'!E13:L13,"A"))-(COUNTIF('02_Entrada_Respuestas'!AK13:AR13,"A")) -> 0 | N13: =(COUNTIF('02_Entrada_Respuestas'!E13:L13,"B"))-(COUNTIF('02_Entrada_Respuestas'!AK13:AR13,"B")) -> 0 | O13: =(COUNTIF('02_Entrada_Respuestas'!E13:L13,"C"))-(COUNTIF('02_Entrada_Respuestas'!AK13:AR13,"C")) -> 0 | P13: =(COUNTIF('02_Entrada_Respuestas'!E13:L13,"D"))-(COUNTIF('02_Entrada_Respuestas'!AK13:AR13,"D")) -> 0 | Q13: =RIGHT(INDEX(M$1:P$1,1,MATCH(MAX(M13:P13),M13:P13,0)),1) -> D | R13: =MAX(M13:P13) -> 0 | S13: =IF(MAX(M13:P13)>=8*0.5,"Alto",IF(MAX(M13:P13)>=8*0.15,"Medio","Mixto/Neutro")) -> Mixto/Neutro | T13: =(COUNTIF('02_Entrada_Respuestas'!Q13:T13,"A"))-(COUNTIF('02_Entrada_Respuestas'!AW13:AZ13,"A")) -> 0 | U13: =(COUNTIF('02_Entrada_Respuestas'!Q13:T13,"B"))-(COUNTIF('02_Entrada_Respuestas'!AW13:AZ13,"B")) -> 0 | V13: =(COUNTIF('02_Entrada_Respuestas'!Q13:T13,"C"))-(COUNTIF('02_Entrada_Respuestas'!AW13:AZ13,"C")) -> 0 | W13: =(COUNTIF('02_Entrada_Respuestas'!Q13:T13,"D"))-(COUNTIF('02_Entrada_Respuestas'!AW13:AZ13,"D")) -> 0 | X13: =RIGHT(INDEX(T$1:W$1,1,MATCH(MAX(T13:W13),T13:W13,0)),1) -> D | Y13: =MAX(T13:W13) -> 0 | Z13: =IF(MAX(T13:W13)>=4*0.5,"Alto",IF(MAX(T13:W13)>=4*0.15,"Medio","Mixto/Neutro")) -> Mixto/Neutro | AA13: =(COUNTIF('02_Entrada_Respuestas'!M13:P13,"A")+COUNTIF('02_Entrada_Respuestas'!U13:AB13,"A"))-(COUNTIF('02_Entrada_Respuestas'!AS13:AV13,"A")+COUNTIF('02_Entrada_Respuestas'!BA13:BH13,"A")) -> 0 | AB13: =(COUNTIF('02_Entrada_Respuestas'!M13:P13,"B")+COUNTIF('02_Entrada_Respuestas'!U13:AB13,"B"))-(COUNTIF('02_Entrada_Respuestas'!AS13:AV13,"B")+COUNTIF('02_Entrada_Respuestas'!BA13:BH13,"B")) -> 0 | AC13: =(COUNTIF('02_Entrada_Respuestas'!M13:P13,"C")+COUNTIF('02_Entrada_Respuestas'!U13:AB13,"C"))-(COUNTIF('02_Entrada_Respuestas'!AS13:AV13,"C")+COUNTIF('02_Entrada_Respuestas'!BA13:BH13,"C")) -> 0 | AD13: =(COUNTIF('02_Entrada_Respuestas'!M13:P13,"D")+COUNTIF('02_Entrada_Respuestas'!U13:AB13,"D"))-(COUNTIF('02_Entrada_Respuestas'!AS13:AV13,"D")+COUNTIF('02_Entrada_Respuestas'!BA13:BH13,"D")) -> 0 | AE13: =RIGHT(INDEX(AA$1:AD$1,1,MATCH(MAX(AA13:AD13),AA13:AD13,0)),1) -> D | AF13: =MAX(AA13:AD13) -> 0 | AG13: =IF(MAX(AA13:AD13)>=12*0.5,"Alto",IF(MAX(AA13:AD13)>=12*0.15,"Medio","Mixto/Neutro")) -> Mixto/Neutro | AH13: =(COUNTIF('02_Entrada_Respuestas'!AC13:AJ13,"A"))-(COUNTIF('02_Entrada_Respuestas'!BI13:BP13,"A")) -> 0 | AI13: =(COUNTIF('02_Entrada_Respuestas'!AC13:AJ13,"B"))-(COUNTIF('02_Entrada_Respuestas'!BI13:BP13,"B")) -> 0 | AJ13: =(COUNTIF('02_Entrada_Respuestas'!AC13:AJ13,"C"))-(COUNTIF('02_Entrada_Respuestas'!BI13:BP13,"C")) -> 0 | AK13: =(COUNTIF('02_Entrada_Respuestas'!AC13:AJ13,"D"))-(COUNTIF('02_Entrada_Respuestas'!BI13:BP13,"D")) -> 0 | AL13: =RIGHT(INDEX(AH$1:AK$1,1,MATCH(MAX(AH13:AK13),AH13:AK13,0)),1) -> D | AM13: =MAX(AH13:AK13) -> 0 | AN13: =IF(MAX(AH13:AK13)>=8*0.5,"Alto",IF(MAX(AH13:AK13)>=8*0.15,"Medio","Mixto/Neutro")) -> Mixto/Neutro
